==4970== Memcheck, a memory error detector
==4970== Copyright (C) 2002-2017, and GNU GPL'd, by Julian Seward et al.
==4970== Using Valgrind-3.15.0-608cb11914-20190413 and LibVEX; rerun with -h for copyright info
==4970== Command: python3.8 full_transceiver_isdbt.py
==4970== 
--4970-- Valgrind options:
--4970--    --leak-check=yes
--4970--    -v
--4970--    --track-origins=yes
--4970--    --read-var-info=yes
--4970-- Contents of /proc/version:
--4970--   Linux version 5.4.0-58-generic (buildd@lcy01-amd64-004) (gcc version 9.3.0 (Ubuntu 9.3.0-17ubuntu1~20.04)) #64-Ubuntu SMP Wed Dec 9 08:16:25 UTC 2020
--4970-- 
--4970-- Arch and hwcaps: AMD64, LittleEndian, amd64-cx16-lzcnt-rdtscp-sse3-ssse3-avx-avx2-bmi-f16c-rdrand
--4970-- Page sizes: currently 4096, max supported 4096
--4970-- Valgrind library directory: /usr/lib/x86_64-linux-gnu/valgrind
--4970-- Reading syms from /usr/bin/python3.8
--4970--    object doesn't have a symbol table
--4970-- Reading syms from /usr/lib/x86_64-linux-gnu/ld-2.31.so
--4970--   Considering /usr/lib/x86_64-linux-gnu/ld-2.31.so ..
--4970--   .. CRC mismatch (computed 975d0390 wanted 30bd717f)
--4970--   Considering /lib/x86_64-linux-gnu/ld-2.31.so ..
--4970--   .. CRC mismatch (computed 975d0390 wanted 30bd717f)
--4970--   Considering /usr/lib/debug/lib/x86_64-linux-gnu/ld-2.31.so ..
--4970--   .. CRC is valid
--4970-- warning: addVar: unknown size (buf)
--4970-- warning: addVar: unknown size (buf)
--4970-- warning: addVar: unknown size (buf)
--4970-- warning: addVar: unknown size (buf)
--4970-- warning: addVar: unknown size (buf)
--4970-- warning: addVar: unknown size (buf)
--4970-- warning: addVar: unknown size (buf)
--4970-- warning: addVar: unknown size (loadcmds)
--4970-- warning: addVar: unknown size (loadcmds)
--4970-- warning: addVar: unknown size (loadcmds)
--4970-- Reading syms from /usr/lib/x86_64-linux-gnu/valgrind/memcheck-amd64-linux
--4970--    object doesn't have a symbol table
--4970--    object doesn't have a dynamic symbol table
--4970-- Scheduler: using generic scheduler lock implementation.
--4970-- Reading suppressions file: /usr/lib/x86_64-linux-gnu/valgrind/default.supp
==4970== embedded gdbserver: reading from /tmp/vgdb-pipe-from-vgdb-to-4970-by-lingles-on-???
==4970== embedded gdbserver: writing to   /tmp/vgdb-pipe-to-vgdb-from-4970-by-lingles-on-???
==4970== embedded gdbserver: shared mem   /tmp/vgdb-pipe-shared-mem-vgdb-4970-by-lingles-on-???
==4970== 
==4970== TO CONTROL THIS PROCESS USING vgdb (which you probably
==4970== don't want to do, unless you know exactly what you're doing,
==4970== or are doing some strange experiment):
==4970==   /usr/lib/x86_64-linux-gnu/valgrind/../../bin/vgdb --pid=4970 ...command...
==4970== 
==4970== TO DEBUG THIS PROCESS USING GDB: start GDB like this
==4970==   /path/to/gdb python3.8
==4970== and then give GDB the following command
==4970==   target remote | /usr/lib/x86_64-linux-gnu/valgrind/../../bin/vgdb --pid=4970
==4970== --pid is optional if only one valgrind process is running
==4970== 
--4970-- REDIR: 0x4022e10 (ld-linux-x86-64.so.2:strlen) redirected to 0x580c9ce2 (???)
--4970-- REDIR: 0x4022be0 (ld-linux-x86-64.so.2:index) redirected to 0x580c9cfc (???)
--4970-- Reading syms from /usr/lib/x86_64-linux-gnu/valgrind/vgpreload_core-amd64-linux.so
--4970--    object doesn't have a symbol table
--4970-- Reading syms from /usr/lib/x86_64-linux-gnu/valgrind/vgpreload_memcheck-amd64-linux.so
--4970--    object doesn't have a symbol table
==4970== WARNING: new redirection conflicts with existing -- ignoring it
--4970--     old: 0x04022e10 (strlen              ) R-> (0000.0) 0x580c9ce2 ???
--4970--     new: 0x04022e10 (strlen              ) R-> (2007.0) 0x0483f060 strlen
--4970-- REDIR: 0x401f5f0 (ld-linux-x86-64.so.2:strcmp) redirected to 0x483ffd0 (strcmp)
--4970-- REDIR: 0x4023370 (ld-linux-x86-64.so.2:mempcpy) redirected to 0x4843a20 (mempcpy)
--4970-- Reading syms from /usr/lib/x86_64-linux-gnu/libc-2.31.so
--4970--   Considering /usr/lib/x86_64-linux-gnu/libc-2.31.so ..
--4970--   .. CRC mismatch (computed 86b78530 wanted e380f01c)
--4970--   Considering /lib/x86_64-linux-gnu/libc-2.31.so ..
--4970--   .. CRC mismatch (computed 86b78530 wanted e380f01c)
--4970--   Considering /usr/lib/debug/lib/x86_64-linux-gnu/libc-2.31.so ..
--4970--   .. CRC is valid
--4970-- Reading syms from /usr/lib/x86_64-linux-gnu/libpthread-2.31.so
--4970--   Considering /usr/lib/debug/.build-id/e5/4761f7b554d0fcc1562959665d93dffbebdaf0.debug ..
--4970--   .. build-id is valid
--4970-- Reading syms from /usr/lib/x86_64-linux-gnu/libdl-2.31.so
--4970--   Considering /usr/lib/x86_64-linux-gnu/libdl-2.31.so ..
--4970--   .. CRC mismatch (computed b5d487d3 wanted 6ef97e7c)
--4970--   Considering /lib/x86_64-linux-gnu/libdl-2.31.so ..
--4970--   .. CRC mismatch (computed b5d487d3 wanted 6ef97e7c)
--4970--   Considering /usr/lib/debug/lib/x86_64-linux-gnu/libdl-2.31.so ..
--4970--   .. CRC is valid
--4970-- Reading syms from /usr/lib/x86_64-linux-gnu/libutil-2.31.so
--4970--   Considering /usr/lib/x86_64-linux-gnu/libutil-2.31.so ..
--4970--   .. CRC mismatch (computed 66300280 wanted 61afbb9f)
--4970--   Considering /lib/x86_64-linux-gnu/libutil-2.31.so ..
--4970--   .. CRC mismatch (computed 66300280 wanted 61afbb9f)
--4970--   Considering /usr/lib/debug/lib/x86_64-linux-gnu/libutil-2.31.so ..
--4970--   .. CRC is valid
--4970-- Reading syms from /usr/lib/x86_64-linux-gnu/libm-2.31.so
--4970--   Considering /usr/lib/x86_64-linux-gnu/libm-2.31.so ..
--4970--   .. CRC mismatch (computed fcb42c76 wanted f6c95789)
--4970--   Considering /lib/x86_64-linux-gnu/libm-2.31.so ..
--4970--   .. CRC mismatch (computed fcb42c76 wanted f6c95789)
--4970--   Considering /usr/lib/debug/lib/x86_64-linux-gnu/libm-2.31.so ..
--4970--   .. CRC is valid
--4970-- Reading syms from /usr/lib/x86_64-linux-gnu/libexpat.so.1.6.11
--4970--    object doesn't have a symbol table
--4970-- Reading syms from /usr/lib/x86_64-linux-gnu/libz.so.1.2.11
--4970--    object doesn't have a symbol table
--4970-- REDIR: 0x490d600 (libc.so.6:memmove) redirected to 0x48331d0 (_vgnU_ifunc_wrapper)
--4970-- REDIR: 0x490c900 (libc.so.6:strncpy) redirected to 0x48331d0 (_vgnU_ifunc_wrapper)
--4970-- REDIR: 0x490d930 (libc.so.6:strcasecmp) redirected to 0x48331d0 (_vgnU_ifunc_wrapper)
--4970-- REDIR: 0x490c220 (libc.so.6:strcat) redirected to 0x48331d0 (_vgnU_ifunc_wrapper)
--4970-- REDIR: 0x490c960 (libc.so.6:rindex) redirected to 0x48331d0 (_vgnU_ifunc_wrapper)
--4970-- REDIR: 0x490edd0 (libc.so.6:rawmemchr) redirected to 0x48331d0 (_vgnU_ifunc_wrapper)
--4970-- REDIR: 0x4929e60 (libc.so.6:wmemchr) redirected to 0x48331d0 (_vgnU_ifunc_wrapper)
--4970-- REDIR: 0x49299a0 (libc.so.6:wcscmp) redirected to 0x48331d0 (_vgnU_ifunc_wrapper)
--4970-- REDIR: 0x490d760 (libc.so.6:mempcpy) redirected to 0x48331d0 (_vgnU_ifunc_wrapper)
--4970-- REDIR: 0x490d590 (libc.so.6:bcmp) redirected to 0x48331d0 (_vgnU_ifunc_wrapper)
--4970-- REDIR: 0x490c890 (libc.so.6:strncmp) redirected to 0x48331d0 (_vgnU_ifunc_wrapper)
--4970-- REDIR: 0x490c2d0 (libc.so.6:strcmp) redirected to 0x48331d0 (_vgnU_ifunc_wrapper)
--4970-- REDIR: 0x490d6c0 (libc.so.6:memset) redirected to 0x48331d0 (_vgnU_ifunc_wrapper)
--4970-- REDIR: 0x4929960 (libc.so.6:wcschr) redirected to 0x48331d0 (_vgnU_ifunc_wrapper)
--4970-- REDIR: 0x490c7f0 (libc.so.6:strnlen) redirected to 0x48331d0 (_vgnU_ifunc_wrapper)
--4970-- REDIR: 0x490c3b0 (libc.so.6:strcspn) redirected to 0x48331d0 (_vgnU_ifunc_wrapper)
--4970-- REDIR: 0x490d980 (libc.so.6:strncasecmp) redirected to 0x48331d0 (_vgnU_ifunc_wrapper)
--4970-- REDIR: 0x490c350 (libc.so.6:strcpy) redirected to 0x48331d0 (_vgnU_ifunc_wrapper)
--4970-- REDIR: 0x490dad0 (libc.so.6:memcpy@@GLIBC_2.14) redirected to 0x48331d0 (_vgnU_ifunc_wrapper)
--4970-- REDIR: 0x492b0d0 (libc.so.6:wcsnlen) redirected to 0x48331d0 (_vgnU_ifunc_wrapper)
--4970-- REDIR: 0x49299e0 (libc.so.6:wcscpy) redirected to 0x48331d0 (_vgnU_ifunc_wrapper)
--4970-- REDIR: 0x490c9a0 (libc.so.6:strpbrk) redirected to 0x48331d0 (_vgnU_ifunc_wrapper)
--4970-- REDIR: 0x490c280 (libc.so.6:index) redirected to 0x48331d0 (_vgnU_ifunc_wrapper)
--4970-- REDIR: 0x490c7b0 (libc.so.6:strlen) redirected to 0x48331d0 (_vgnU_ifunc_wrapper)
--4970-- REDIR: 0x4915d20 (libc.so.6:memrchr) redirected to 0x48331d0 (_vgnU_ifunc_wrapper)
--4970-- REDIR: 0x490d9d0 (libc.so.6:strcasecmp_l) redirected to 0x48331d0 (_vgnU_ifunc_wrapper)
--4970-- REDIR: 0x490d550 (libc.so.6:memchr) redirected to 0x48331d0 (_vgnU_ifunc_wrapper)
--4970-- REDIR: 0x4929ab0 (libc.so.6:wcslen) redirected to 0x48331d0 (_vgnU_ifunc_wrapper)
--4970-- REDIR: 0x490cc60 (libc.so.6:strspn) redirected to 0x48331d0 (_vgnU_ifunc_wrapper)
--4970-- REDIR: 0x490d8d0 (libc.so.6:stpncpy) redirected to 0x48331d0 (_vgnU_ifunc_wrapper)
--4970-- REDIR: 0x490d870 (libc.so.6:stpcpy) redirected to 0x48331d0 (_vgnU_ifunc_wrapper)
--4970-- REDIR: 0x490ee10 (libc.so.6:strchrnul) redirected to 0x48331d0 (_vgnU_ifunc_wrapper)
--4970-- REDIR: 0x490da20 (libc.so.6:strncasecmp_l) redirected to 0x48331d0 (_vgnU_ifunc_wrapper)
--4970-- REDIR: 0x49f5490 (libc.so.6:__strrchr_avx2) redirected to 0x483ea10 (rindex)
--4970-- REDIR: 0x4907260 (libc.so.6:malloc) redirected to 0x483b780 (malloc)
--4970-- REDIR: 0x49f8670 (libc.so.6:__memcpy_avx_unaligned_erms) redirected to 0x48429f0 (memmove)
--4970-- REDIR: 0x49f0b60 (libc.so.6:__strcmp_avx2) redirected to 0x483fed0 (strcmp)
--4970-- REDIR: 0x49f5660 (libc.so.6:__strlen_avx2) redirected to 0x483ef40 (strlen)
--4970-- REDIR: 0x49f0fa0 (libc.so.6:__strncmp_avx2) redirected to 0x483f670 (strncmp)
--4970-- REDIR: 0x49f14c0 (libc.so.6:__memchr_avx2) redirected to 0x4840050 (memchr)
--4970-- REDIR: 0x49f5070 (libc.so.6:__strchr_avx2) redirected to 0x483ebf0 (index)
--4970-- REDIR: 0x49f52a0 (libc.so.6:__strchrnul_avx2) redirected to 0x4843540 (strchrnul)
--4970-- REDIR: 0x49f8650 (libc.so.6:__mempcpy_avx_unaligned_erms) redirected to 0x4843660 (mempcpy)
--4970-- REDIR: 0x4907850 (libc.so.6:free) redirected to 0x483c9d0 (free)
--4970-- REDIR: 0x49f7890 (libc.so.6:__stpcpy_avx2) redirected to 0x4842300 (stpcpy)
--4970-- REDIR: 0x4908c90 (libc.so.6:calloc) redirected to 0x483dce0 (calloc)
--4970-- REDIR: 0x49f5800 (libc.so.6:__strnlen_avx2) redirected to 0x483eee0 (strnlen)
--4970-- REDIR: 0x49f9fd0 (libc.so.6:__wcslen_avx2) redirected to 0x4844050 (wcslen)
--4970-- REDIR: 0x49f9240 (libc.so.6:__wcscmp_avx2) redirected to 0x48440e0 (wcscmp)
--4970-- REDIR: 0x49f8af0 (libc.so.6:__memset_avx2_unaligned_erms) redirected to 0x48428e0 (memset)
--4970-- REDIR: 0x49f9bb0 (libc.so.6:__wcschr_avx2) redirected to 0x4844260 (wcschr)
--4970-- REDIR: 0x49fa190 (libc.so.6:__wcsnlen_avx2) redirected to 0x4844080 (wcsnlen)
--4970-- REDIR: 0x49ea820 (libc.so.6:__wcscpy_ssse3) redirected to 0x4844190 (wcscpy)
--4970-- REDIR: 0x4908000 (libc.so.6:realloc) redirected to 0x483df30 (realloc)
--4970-- REDIR: 0x49f1c50 (libc.so.6:__memcmp_avx2_movbe) redirected to 0x48421e0 (bcmp)
==4970== Invalid read of size 4
==4970==    at 0x5B8222: PyObject_Free (in /usr/bin/python3.8)
==4970==    by 0x5CDC77: ??? (in /usr/bin/python3.8)
==4970==    by 0x5CFD32: PyDict_SetDefault (in /usr/bin/python3.8)
==4970==    by 0x575811: PyUnicode_InternFromString (in /usr/bin/python3.8)
==4970==    by 0x69D1C0: ??? (in /usr/bin/python3.8)
==4970==    by 0x5A1289: PyType_Ready (in /usr/bin/python3.8)
==4970==    by 0x6A4772: _PyTypes_Init (in /usr/bin/python3.8)
==4970==    by 0x67FD5B: Py_InitializeFromConfig (in /usr/bin/python3.8)
==4970==    by 0x6B63F5: ??? (in /usr/bin/python3.8)
==4970==    by 0x6B6450: ??? (in /usr/bin/python3.8)
==4970==    by 0x6B64BC: Py_BytesMain (in /usr/bin/python3.8)
==4970==    by 0x48910B2: (below main) (libc-start.c:308)
==4970==  Address 0x4c2e020 is 16 bytes before a block of size 28 alloc'd
==4970==    at 0x483B7F3: malloc (in /usr/lib/x86_64-linux-gnu/valgrind/vgpreload_memcheck-amd64-linux.so)
==4970==    by 0x6A39EA: _PyMem_RawWcsdup (in /usr/bin/python3.8)
==4970==    by 0x681588: PyConfig_SetString (in /usr/bin/python3.8)
==4970==    by 0x68190E: _PyConfig_Copy (in /usr/bin/python3.8)
==4970==    by 0x67FD04: Py_InitializeFromConfig (in /usr/bin/python3.8)
==4970==    by 0x6B63F5: ??? (in /usr/bin/python3.8)
==4970==    by 0x6B6450: ??? (in /usr/bin/python3.8)
==4970==    by 0x6B64BC: Py_BytesMain (in /usr/bin/python3.8)
==4970==    by 0x48910B2: (below main) (libc-start.c:308)
==4970== 
==4970== Invalid read of size 4
==4970==    at 0x5B8222: PyObject_Free (in /usr/bin/python3.8)
==4970==    by 0x5CDC77: ??? (in /usr/bin/python3.8)
==4970==    by 0x5CEEEF: PyDict_SetItem (in /usr/bin/python3.8)
==4970==    by 0x5A04BE: PyType_Ready (in /usr/bin/python3.8)
==4970==    by 0x6A4772: _PyTypes_Init (in /usr/bin/python3.8)
==4970==    by 0x67FD5B: Py_InitializeFromConfig (in /usr/bin/python3.8)
==4970==    by 0x6B63F5: ??? (in /usr/bin/python3.8)
==4970==    by 0x6B6450: ??? (in /usr/bin/python3.8)
==4970==    by 0x6B64BC: Py_BytesMain (in /usr/bin/python3.8)
==4970==    by 0x48910B2: (below main) (libc-start.c:308)
==4970==  Address 0x4c2f020 is 624 bytes inside a block of size 2,208 free'd
==4970==    at 0x483CA3F: free (in /usr/lib/x86_64-linux-gnu/valgrind/vgpreload_memcheck-amd64-linux.so)
==4970==    by 0x5CDC77: ??? (in /usr/bin/python3.8)
==4970==    by 0x5CFD32: PyDict_SetDefault (in /usr/bin/python3.8)
==4970==    by 0x575811: PyUnicode_InternFromString (in /usr/bin/python3.8)
==4970==    by 0x5A0226: PyType_Ready (in /usr/bin/python3.8)
==4970==    by 0x6A4772: _PyTypes_Init (in /usr/bin/python3.8)
==4970==    by 0x67FD5B: Py_InitializeFromConfig (in /usr/bin/python3.8)
==4970==    by 0x6B63F5: ??? (in /usr/bin/python3.8)
==4970==    by 0x6B6450: ??? (in /usr/bin/python3.8)
==4970==    by 0x6B64BC: Py_BytesMain (in /usr/bin/python3.8)
==4970==    by 0x48910B2: (below main) (libc-start.c:308)
==4970==  Block was alloc'd at
==4970==    at 0x483B7F3: malloc (in /usr/lib/x86_64-linux-gnu/valgrind/vgpreload_memcheck-amd64-linux.so)
==4970==    by 0x5B8F63: PyObject_Malloc (in /usr/bin/python3.8)
==4970==    by 0x5CDC05: ??? (in /usr/bin/python3.8)
==4970==    by 0x5CFD32: PyDict_SetDefault (in /usr/bin/python3.8)
==4970==    by 0x575811: PyUnicode_InternFromString (in /usr/bin/python3.8)
==4970==    by 0x69D1C0: ??? (in /usr/bin/python3.8)
==4970==    by 0x5A1289: PyType_Ready (in /usr/bin/python3.8)
==4970==    by 0x6A4772: _PyTypes_Init (in /usr/bin/python3.8)
==4970==    by 0x67FD5B: Py_InitializeFromConfig (in /usr/bin/python3.8)
==4970==    by 0x6B63F5: ??? (in /usr/bin/python3.8)
==4970==    by 0x6B6450: ??? (in /usr/bin/python3.8)
==4970==    by 0x6B64BC: Py_BytesMain (in /usr/bin/python3.8)
==4970== 
==4970== Invalid read of size 4
==4970==    at 0x5B8222: PyObject_Free (in /usr/bin/python3.8)
==4970==    by 0x5CDC77: ??? (in /usr/bin/python3.8)
==4970==    by 0x5CEEEF: PyDict_SetItem (in /usr/bin/python3.8)
==4970==    by 0x59E4CD: PyType_Ready (in /usr/bin/python3.8)
==4970==    by 0x6A47A8: _PyTypes_Init (in /usr/bin/python3.8)
==4970==    by 0x67FD5B: Py_InitializeFromConfig (in /usr/bin/python3.8)
==4970==    by 0x6B63F5: ??? (in /usr/bin/python3.8)
==4970==    by 0x6B6450: ??? (in /usr/bin/python3.8)
==4970==    by 0x6B64BC: Py_BytesMain (in /usr/bin/python3.8)
==4970==    by 0x48910B2: (below main) (libc-start.c:308)
==4970==  Address 0x4c31020 is 16 bytes inside a block of size 576 free'd
==4970==    at 0x483CA3F: free (in /usr/lib/x86_64-linux-gnu/valgrind/vgpreload_memcheck-amd64-linux.so)
==4970==    by 0x5CDC77: ??? (in /usr/bin/python3.8)
==4970==    by 0x5CEEEF: PyDict_SetItem (in /usr/bin/python3.8)
==4970==    by 0x5A04BE: PyType_Ready (in /usr/bin/python3.8)
==4970==    by 0x6A4784: _PyTypes_Init (in /usr/bin/python3.8)
==4970==    by 0x67FD5B: Py_InitializeFromConfig (in /usr/bin/python3.8)
==4970==    by 0x6B63F5: ??? (in /usr/bin/python3.8)
==4970==    by 0x6B6450: ??? (in /usr/bin/python3.8)
==4970==    by 0x6B64BC: Py_BytesMain (in /usr/bin/python3.8)
==4970==    by 0x48910B2: (below main) (libc-start.c:308)
==4970==  Block was alloc'd at
==4970==    at 0x483B7F3: malloc (in /usr/lib/x86_64-linux-gnu/valgrind/vgpreload_memcheck-amd64-linux.so)
==4970==    by 0x5B8F63: PyObject_Malloc (in /usr/bin/python3.8)
==4970==    by 0x5CDC05: ??? (in /usr/bin/python3.8)
==4970==    by 0x5CEEEF: PyDict_SetItem (in /usr/bin/python3.8)
==4970==    by 0x5A02FE: PyType_Ready (in /usr/bin/python3.8)
==4970==    by 0x6A4784: _PyTypes_Init (in /usr/bin/python3.8)
==4970==    by 0x67FD5B: Py_InitializeFromConfig (in /usr/bin/python3.8)
==4970==    by 0x6B63F5: ??? (in /usr/bin/python3.8)
==4970==    by 0x6B6450: ??? (in /usr/bin/python3.8)
==4970==    by 0x6B64BC: Py_BytesMain (in /usr/bin/python3.8)
==4970==    by 0x48910B2: (below main) (libc-start.c:308)
==4970== 
==4970== Invalid read of size 4
==4970==    at 0x5B8222: PyObject_Free (in /usr/bin/python3.8)
==4970==    by 0x5CDC77: ??? (in /usr/bin/python3.8)
==4970==    by 0x5CEEEF: PyDict_SetItem (in /usr/bin/python3.8)
==4970==    by 0x5A02FE: PyType_Ready (in /usr/bin/python3.8)
==4970==    by 0x6A47F0: _PyTypes_Init (in /usr/bin/python3.8)
==4970==    by 0x67FD5B: Py_InitializeFromConfig (in /usr/bin/python3.8)
==4970==    by 0x6B63F5: ??? (in /usr/bin/python3.8)
==4970==    by 0x6B6450: ??? (in /usr/bin/python3.8)
==4970==    by 0x6B64BC: Py_BytesMain (in /usr/bin/python3.8)
==4970==    by 0x48910B2: (below main) (libc-start.c:308)
==4970==  Address 0x4c34020 is 1,008 bytes inside a block of size 1,112 free'd
==4970==    at 0x483CA3F: free (in /usr/lib/x86_64-linux-gnu/valgrind/vgpreload_memcheck-amd64-linux.so)
==4970==    by 0x5CDC77: ??? (in /usr/bin/python3.8)
==4970==    by 0x5CEEEF: PyDict_SetItem (in /usr/bin/python3.8)
==4970==    by 0x59E4CD: PyType_Ready (in /usr/bin/python3.8)
==4970==    by 0x6A47CC: _PyTypes_Init (in /usr/bin/python3.8)
==4970==    by 0x67FD5B: Py_InitializeFromConfig (in /usr/bin/python3.8)
==4970==    by 0x6B63F5: ??? (in /usr/bin/python3.8)
==4970==    by 0x6B6450: ??? (in /usr/bin/python3.8)
==4970==    by 0x6B64BC: Py_BytesMain (in /usr/bin/python3.8)
==4970==    by 0x48910B2: (below main) (libc-start.c:308)
==4970==  Block was alloc'd at
==4970==    at 0x483B7F3: malloc (in /usr/lib/x86_64-linux-gnu/valgrind/vgpreload_memcheck-amd64-linux.so)
==4970==    by 0x5B8F63: PyObject_Malloc (in /usr/bin/python3.8)
==4970==    by 0x5CDC05: ??? (in /usr/bin/python3.8)
==4970==    by 0x5CEEEF: PyDict_SetItem (in /usr/bin/python3.8)
==4970==    by 0x59E4CD: PyType_Ready (in /usr/bin/python3.8)
==4970==    by 0x6A47CC: _PyTypes_Init (in /usr/bin/python3.8)
==4970==    by 0x67FD5B: Py_InitializeFromConfig (in /usr/bin/python3.8)
==4970==    by 0x6B63F5: ??? (in /usr/bin/python3.8)
==4970==    by 0x6B6450: ??? (in /usr/bin/python3.8)
==4970==    by 0x6B64BC: Py_BytesMain (in /usr/bin/python3.8)
==4970==    by 0x48910B2: (below main) (libc-start.c:308)
==4970== 
==4970== Invalid read of size 4
==4970==    at 0x5B8222: PyObject_Free (in /usr/bin/python3.8)
==4970==    by 0x5CDC77: ??? (in /usr/bin/python3.8)
==4970==    by 0x5CEEEF: PyDict_SetItem (in /usr/bin/python3.8)
==4970==    by 0x59F100: PyType_Ready (in /usr/bin/python3.8)
==4970==    by 0x6A4892: _PyTypes_Init (in /usr/bin/python3.8)
==4970==    by 0x67FD5B: Py_InitializeFromConfig (in /usr/bin/python3.8)
==4970==    by 0x6B63F5: ??? (in /usr/bin/python3.8)
==4970==    by 0x6B6450: ??? (in /usr/bin/python3.8)
==4970==    by 0x6B64BC: Py_BytesMain (in /usr/bin/python3.8)
==4970==    by 0x48910B2: (below main) (libc-start.c:308)
==4970==  Address 0x4c3a020 is 208 bytes inside a block of size 576 free'd
==4970==    at 0x483CA3F: free (in /usr/lib/x86_64-linux-gnu/valgrind/vgpreload_memcheck-amd64-linux.so)
==4970==    by 0x5CDC77: ??? (in /usr/bin/python3.8)
==4970==    by 0x5CEEEF: PyDict_SetItem (in /usr/bin/python3.8)
==4970==    by 0x59E747: PyType_Ready (in /usr/bin/python3.8)
==4970==    by 0x6A486E: _PyTypes_Init (in /usr/bin/python3.8)
==4970==    by 0x67FD5B: Py_InitializeFromConfig (in /usr/bin/python3.8)
==4970==    by 0x6B63F5: ??? (in /usr/bin/python3.8)
==4970==    by 0x6B6450: ??? (in /usr/bin/python3.8)
==4970==    by 0x6B64BC: Py_BytesMain (in /usr/bin/python3.8)
==4970==    by 0x48910B2: (below main) (libc-start.c:308)
==4970==  Block was alloc'd at
==4970==    at 0x483B7F3: malloc (in /usr/lib/x86_64-linux-gnu/valgrind/vgpreload_memcheck-amd64-linux.so)
==4970==    by 0x5B8F63: PyObject_Malloc (in /usr/bin/python3.8)
==4970==    by 0x5CDC05: ??? (in /usr/bin/python3.8)
==4970==    by 0x5CEEEF: PyDict_SetItem (in /usr/bin/python3.8)
==4970==    by 0x59E4CD: PyType_Ready (in /usr/bin/python3.8)
==4970==    by 0x6A486E: _PyTypes_Init (in /usr/bin/python3.8)
==4970==    by 0x67FD5B: Py_InitializeFromConfig (in /usr/bin/python3.8)
==4970==    by 0x6B63F5: ??? (in /usr/bin/python3.8)
==4970==    by 0x6B6450: ??? (in /usr/bin/python3.8)
==4970==    by 0x6B64BC: Py_BytesMain (in /usr/bin/python3.8)
==4970==    by 0x48910B2: (below main) (libc-start.c:308)
==4970== 
==4970== Invalid read of size 4
==4970==    at 0x5B8222: PyObject_Free (in /usr/bin/python3.8)
==4970==    by 0x5CDC77: ??? (in /usr/bin/python3.8)
==4970==    by 0x5D0B1E: PyDict_SetItemString (in /usr/bin/python3.8)
==4970==    by 0x6AF96A: _PyBuiltins_AddExceptions (in /usr/bin/python3.8)
==4970==    by 0x67FE63: Py_InitializeFromConfig (in /usr/bin/python3.8)
==4970==    by 0x6B63F5: ??? (in /usr/bin/python3.8)
==4970==    by 0x6B6450: ??? (in /usr/bin/python3.8)
==4970==    by 0x6B64BC: Py_BytesMain (in /usr/bin/python3.8)
==4970==    by 0x48910B2: (below main) (libc-start.c:308)
==4970==  Address 0x4c4e020 is 192 bytes inside a block of size 1,112 free'd
==4970==    at 0x483CA3F: free (in /usr/lib/x86_64-linux-gnu/valgrind/vgpreload_memcheck-amd64-linux.so)
==4970==    by 0x5CDC77: ??? (in /usr/bin/python3.8)
==4970==    by 0x5CEEEF: PyDict_SetItem (in /usr/bin/python3.8)
==4970==    by 0x5BFE1F: PyObject_SetAttr (in /usr/bin/python3.8)
==4970==    by 0x5C235C: ??? (in /usr/bin/python3.8)
==4970==    by 0x6A55B1: PyModule_AddFunctions (in /usr/bin/python3.8)
==4970==    by 0x6A5829: _PyModule_CreateInitialized (in /usr/bin/python3.8)
==4970==    by 0x5FE218: _PyBuiltin_Init (in /usr/bin/python3.8)
==4970==    by 0x67FE1D: Py_InitializeFromConfig (in /usr/bin/python3.8)
==4970==    by 0x6B63F5: ??? (in /usr/bin/python3.8)
==4970==    by 0x6B6450: ??? (in /usr/bin/python3.8)
==4970==    by 0x6B64BC: Py_BytesMain (in /usr/bin/python3.8)
==4970==  Block was alloc'd at
==4970==    at 0x483B7F3: malloc (in /usr/lib/x86_64-linux-gnu/valgrind/vgpreload_memcheck-amd64-linux.so)
==4970==    by 0x5B8F63: PyObject_Malloc (in /usr/bin/python3.8)
==4970==    by 0x5CDC05: ??? (in /usr/bin/python3.8)
==4970==    by 0x5CEEEF: PyDict_SetItem (in /usr/bin/python3.8)
==4970==    by 0x5BFE1F: PyObject_SetAttr (in /usr/bin/python3.8)
==4970==    by 0x5C235C: ??? (in /usr/bin/python3.8)
==4970==    by 0x6A55B1: PyModule_AddFunctions (in /usr/bin/python3.8)
==4970==    by 0x6A5829: _PyModule_CreateInitialized (in /usr/bin/python3.8)
==4970==    by 0x5FE218: _PyBuiltin_Init (in /usr/bin/python3.8)
==4970==    by 0x67FE1D: Py_InitializeFromConfig (in /usr/bin/python3.8)
==4970==    by 0x6B63F5: ??? (in /usr/bin/python3.8)
==4970==    by 0x6B6450: ??? (in /usr/bin/python3.8)
==4970== 
==4970== Invalid read of size 4
==4970==    at 0x5B9C3A: PyMem_Realloc (in /usr/bin/python3.8)
==4970==    by 0x5EA784: PyList_Append (in /usr/bin/python3.8)
==4970==    by 0x54DC88: ??? (in /usr/bin/python3.8)
==4970==    by 0x54DD83: ??? (in /usr/bin/python3.8)
==4970==    by 0x54E328: ??? (in /usr/bin/python3.8)
==4970==    by 0x54DE61: ??? (in /usr/bin/python3.8)
==4970==    by 0x54E312: ??? (in /usr/bin/python3.8)
==4970==    by 0x6808F4: PyMarshal_ReadObjectFromString (in /usr/bin/python3.8)
==4970==    by 0x68310F: PyImport_ImportFrozenModuleObject (in /usr/bin/python3.8)
==4970==    by 0x6831B1: PyImport_ImportFrozenModule (in /usr/bin/python3.8)
==4970==    by 0x67EDC0: ??? (in /usr/bin/python3.8)
==4970==    by 0x67FF0B: Py_InitializeFromConfig (in /usr/bin/python3.8)
==4970==  Address 0x4c52020 is 16 bytes before a block of size 76 alloc'd
==4970==    at 0x483B7F3: malloc (in /usr/lib/x86_64-linux-gnu/valgrind/vgpreload_memcheck-amd64-linux.so)
==4970==    by 0x6A39EA: _PyMem_RawWcsdup (in /usr/bin/python3.8)
==4970==    by 0x67F9F1: ??? (in /usr/bin/python3.8)
==4970==    by 0x67FBA5: _PyConfig_WritePathConfig (in /usr/bin/python3.8)
==4970==    by 0x67FEDF: Py_InitializeFromConfig (in /usr/bin/python3.8)
==4970==    by 0x6B63F5: ??? (in /usr/bin/python3.8)
==4970==    by 0x6B6450: ??? (in /usr/bin/python3.8)
==4970==    by 0x6B64BC: Py_BytesMain (in /usr/bin/python3.8)
==4970==    by 0x48910B2: (below main) (libc-start.c:308)
==4970== 
==4970== Invalid read of size 4
==4970==    at 0x5B9C3A: PyMem_Realloc (in /usr/bin/python3.8)
==4970==    by 0x5EA784: PyList_Append (in /usr/bin/python3.8)
==4970==    by 0x54DC88: ??? (in /usr/bin/python3.8)
==4970==    by 0x54DD35: ??? (in /usr/bin/python3.8)
==4970==    by 0x54E328: ??? (in /usr/bin/python3.8)
==4970==    by 0x54DD35: ??? (in /usr/bin/python3.8)
==4970==    by 0x54E312: ??? (in /usr/bin/python3.8)
==4970==    by 0x54DE61: ??? (in /usr/bin/python3.8)
==4970==    by 0x54E312: ??? (in /usr/bin/python3.8)
==4970==    by 0x6808F4: PyMarshal_ReadObjectFromString (in /usr/bin/python3.8)
==4970==    by 0x68310F: PyImport_ImportFrozenModuleObject (in /usr/bin/python3.8)
==4970==    by 0x6831B1: PyImport_ImportFrozenModule (in /usr/bin/python3.8)
==4970==  Address 0x4c52020 is 16 bytes before a block of size 76 alloc'd
==4970==    at 0x483B7F3: malloc (in /usr/lib/x86_64-linux-gnu/valgrind/vgpreload_memcheck-amd64-linux.so)
==4970==    by 0x6A39EA: _PyMem_RawWcsdup (in /usr/bin/python3.8)
==4970==    by 0x67F9F1: ??? (in /usr/bin/python3.8)
==4970==    by 0x67FBA5: _PyConfig_WritePathConfig (in /usr/bin/python3.8)
==4970==    by 0x67FEDF: Py_InitializeFromConfig (in /usr/bin/python3.8)
==4970==    by 0x6B63F5: ??? (in /usr/bin/python3.8)
==4970==    by 0x6B6450: ??? (in /usr/bin/python3.8)
==4970==    by 0x6B64BC: Py_BytesMain (in /usr/bin/python3.8)
==4970==    by 0x48910B2: (below main) (libc-start.c:308)
==4970== 
==4970== Invalid read of size 4
==4970==    at 0x5B9C3A: PyMem_Realloc (in /usr/bin/python3.8)
==4970==    by 0x5EA784: PyList_Append (in /usr/bin/python3.8)
==4970==    by 0x54DC88: ??? (in /usr/bin/python3.8)
==4970==    by 0x54DDD1: ??? (in /usr/bin/python3.8)
==4970==    by 0x54E328: ??? (in /usr/bin/python3.8)
==4970==    by 0x54DE61: ??? (in /usr/bin/python3.8)
==4970==    by 0x54E312: ??? (in /usr/bin/python3.8)
==4970==    by 0x6808F4: PyMarshal_ReadObjectFromString (in /usr/bin/python3.8)
==4970==    by 0x68310F: PyImport_ImportFrozenModuleObject (in /usr/bin/python3.8)
==4970==    by 0x6831B1: PyImport_ImportFrozenModule (in /usr/bin/python3.8)
==4970==    by 0x67EDC0: ??? (in /usr/bin/python3.8)
==4970==    by 0x67FF0B: Py_InitializeFromConfig (in /usr/bin/python3.8)
==4970==  Address 0x4c52020 is 16 bytes before a block of size 76 alloc'd
==4970==    at 0x483B7F3: malloc (in /usr/lib/x86_64-linux-gnu/valgrind/vgpreload_memcheck-amd64-linux.so)
==4970==    by 0x6A39EA: _PyMem_RawWcsdup (in /usr/bin/python3.8)
==4970==    by 0x67F9F1: ??? (in /usr/bin/python3.8)
==4970==    by 0x67FBA5: _PyConfig_WritePathConfig (in /usr/bin/python3.8)
==4970==    by 0x67FEDF: Py_InitializeFromConfig (in /usr/bin/python3.8)
==4970==    by 0x6B63F5: ??? (in /usr/bin/python3.8)
==4970==    by 0x6B6450: ??? (in /usr/bin/python3.8)
==4970==    by 0x6B64BC: Py_BytesMain (in /usr/bin/python3.8)
==4970==    by 0x48910B2: (below main) (libc-start.c:308)
==4970== 
==4970== Invalid read of size 4
==4970==    at 0x5B9C3A: PyMem_Realloc (in /usr/bin/python3.8)
==4970==    by 0x5EA784: PyList_Append (in /usr/bin/python3.8)
==4970==    by 0x54DC88: ??? (in /usr/bin/python3.8)
==4970==    by 0x54E394: ??? (in /usr/bin/python3.8)
==4970==    by 0x54DE61: ??? (in /usr/bin/python3.8)
==4970==    by 0x54E312: ??? (in /usr/bin/python3.8)
==4970==    by 0x6808F4: PyMarshal_ReadObjectFromString (in /usr/bin/python3.8)
==4970==    by 0x68310F: PyImport_ImportFrozenModuleObject (in /usr/bin/python3.8)
==4970==    by 0x6831B1: PyImport_ImportFrozenModule (in /usr/bin/python3.8)
==4970==    by 0x67EDC0: ??? (in /usr/bin/python3.8)
==4970==    by 0x67FF0B: Py_InitializeFromConfig (in /usr/bin/python3.8)
==4970==    by 0x6B63F5: ??? (in /usr/bin/python3.8)
==4970==  Address 0x4c53020 is 416 bytes inside a block of size 1,008 free'd
==4970==    at 0x483DFAF: realloc (in /usr/lib/x86_64-linux-gnu/valgrind/vgpreload_memcheck-amd64-linux.so)
==4970==    by 0x5EA784: PyList_Append (in /usr/bin/python3.8)
==4970==    by 0x54DC88: ??? (in /usr/bin/python3.8)
==4970==    by 0x54DD83: ??? (in /usr/bin/python3.8)
==4970==    by 0x54E328: ??? (in /usr/bin/python3.8)
==4970==    by 0x54DE61: ??? (in /usr/bin/python3.8)
==4970==    by 0x54E312: ??? (in /usr/bin/python3.8)
==4970==    by 0x54DE61: ??? (in /usr/bin/python3.8)
==4970==    by 0x54E312: ??? (in /usr/bin/python3.8)
==4970==    by 0x6808F4: PyMarshal_ReadObjectFromString (in /usr/bin/python3.8)
==4970==    by 0x68310F: PyImport_ImportFrozenModuleObject (in /usr/bin/python3.8)
==4970==    by 0x6831B1: PyImport_ImportFrozenModule (in /usr/bin/python3.8)
==4970==  Block was alloc'd at
==4970==    at 0x483DFAF: realloc (in /usr/lib/x86_64-linux-gnu/valgrind/vgpreload_memcheck-amd64-linux.so)
==4970==    by 0x5EA784: PyList_Append (in /usr/bin/python3.8)
==4970==    by 0x54DC88: ??? (in /usr/bin/python3.8)
==4970==    by 0x54DDD1: ??? (in /usr/bin/python3.8)
==4970==    by 0x54E328: ??? (in /usr/bin/python3.8)
==4970==    by 0x54DE61: ??? (in /usr/bin/python3.8)
==4970==    by 0x54E312: ??? (in /usr/bin/python3.8)
==4970==    by 0x6808F4: PyMarshal_ReadObjectFromString (in /usr/bin/python3.8)
==4970==    by 0x68310F: PyImport_ImportFrozenModuleObject (in /usr/bin/python3.8)
==4970==    by 0x6831B1: PyImport_ImportFrozenModule (in /usr/bin/python3.8)
==4970==    by 0x67EDC0: ??? (in /usr/bin/python3.8)
==4970==    by 0x67FF0B: Py_InitializeFromConfig (in /usr/bin/python3.8)
==4970== 
==4970== Invalid read of size 4
==4970==    at 0x5B8222: PyObject_Free (in /usr/bin/python3.8)
==4970==    by 0x5CDC77: ??? (in /usr/bin/python3.8)
==4970==    by 0x5CEEEF: PyDict_SetItem (in /usr/bin/python3.8)
==4970==    by 0x56ADFF: _PyEval_EvalFrameDefault (in /usr/bin/python3.8)
==4970==    by 0x568229: _PyEval_EvalCodeWithName (in /usr/bin/python3.8)
==4970==    by 0x68C1E6: PyEval_EvalCode (in /usr/bin/python3.8)
==4970==    by 0x683D86: ??? (in /usr/bin/python3.8)
==4970==    by 0x68314C: PyImport_ImportFrozenModuleObject (in /usr/bin/python3.8)
==4970==    by 0x6831B1: PyImport_ImportFrozenModule (in /usr/bin/python3.8)
==4970==    by 0x67EDC0: ??? (in /usr/bin/python3.8)
==4970==    by 0x67FF0B: Py_InitializeFromConfig (in /usr/bin/python3.8)
==4970==    by 0x6B63F5: ??? (in /usr/bin/python3.8)
==4970==  Address 0x4c5e020 is 848 bytes inside a block of size 1,864 free'd
==4970==    at 0x483CA3F: free (in /usr/lib/x86_64-linux-gnu/valgrind/vgpreload_memcheck-amd64-linux.so)
==4970==    by 0x5EB98C: ??? (in /usr/bin/python3.8)
==4970==    by 0x680907: PyMarshal_ReadObjectFromString (in /usr/bin/python3.8)
==4970==    by 0x68310F: PyImport_ImportFrozenModuleObject (in /usr/bin/python3.8)
==4970==    by 0x6831B1: PyImport_ImportFrozenModule (in /usr/bin/python3.8)
==4970==    by 0x67EDC0: ??? (in /usr/bin/python3.8)
==4970==    by 0x67FF0B: Py_InitializeFromConfig (in /usr/bin/python3.8)
==4970==    by 0x6B63F5: ??? (in /usr/bin/python3.8)
==4970==    by 0x6B6450: ??? (in /usr/bin/python3.8)
==4970==    by 0x6B64BC: Py_BytesMain (in /usr/bin/python3.8)
==4970==    by 0x48910B2: (below main) (libc-start.c:308)
==4970==  Block was alloc'd at
==4970==    at 0x483DFAF: realloc (in /usr/lib/x86_64-linux-gnu/valgrind/vgpreload_memcheck-amd64-linux.so)
==4970==    by 0x5EA784: PyList_Append (in /usr/bin/python3.8)
==4970==    by 0x54DFB2: ??? (in /usr/bin/python3.8)
==4970==    by 0x54DDD1: ??? (in /usr/bin/python3.8)
==4970==    by 0x54E312: ??? (in /usr/bin/python3.8)
==4970==    by 0x54DE61: ??? (in /usr/bin/python3.8)
==4970==    by 0x54E312: ??? (in /usr/bin/python3.8)
==4970==    by 0x6808F4: PyMarshal_ReadObjectFromString (in /usr/bin/python3.8)
==4970==    by 0x68310F: PyImport_ImportFrozenModuleObject (in /usr/bin/python3.8)
==4970==    by 0x6831B1: PyImport_ImportFrozenModule (in /usr/bin/python3.8)
==4970==    by 0x67EDC0: ??? (in /usr/bin/python3.8)
==4970==    by 0x67FF0B: Py_InitializeFromConfig (in /usr/bin/python3.8)
==4970== 
==4970== Invalid read of size 4
==4970==    at 0x5B8222: PyObject_Free (in /usr/bin/python3.8)
==4970==    by 0x5ADAD8: ??? (in /usr/bin/python3.8)
==4970==    by 0x50606B: ??? (in /usr/bin/python3.8)
==4970==    by 0x683167: PyImport_ImportFrozenModuleObject (in /usr/bin/python3.8)
==4970==    by 0x6831B1: PyImport_ImportFrozenModule (in /usr/bin/python3.8)
==4970==    by 0x67EDC0: ??? (in /usr/bin/python3.8)
==4970==    by 0x67FF0B: Py_InitializeFromConfig (in /usr/bin/python3.8)
==4970==    by 0x6B63F5: ??? (in /usr/bin/python3.8)
==4970==    by 0x6B6450: ??? (in /usr/bin/python3.8)
==4970==    by 0x6B64BC: Py_BytesMain (in /usr/bin/python3.8)
==4970==    by 0x48910B2: (below main) (libc-start.c:308)
==4970==  Address 0x4c52020 is 16 bytes before a block of size 76 alloc'd
==4970==    at 0x483B7F3: malloc (in /usr/lib/x86_64-linux-gnu/valgrind/vgpreload_memcheck-amd64-linux.so)
==4970==    by 0x6A39EA: _PyMem_RawWcsdup (in /usr/bin/python3.8)
==4970==    by 0x67F9F1: ??? (in /usr/bin/python3.8)
==4970==    by 0x67FBA5: _PyConfig_WritePathConfig (in /usr/bin/python3.8)
==4970==    by 0x67FEDF: Py_InitializeFromConfig (in /usr/bin/python3.8)
==4970==    by 0x6B63F5: ??? (in /usr/bin/python3.8)
==4970==    by 0x6B6450: ??? (in /usr/bin/python3.8)
==4970==    by 0x6B64BC: Py_BytesMain (in /usr/bin/python3.8)
==4970==    by 0x48910B2: (below main) (libc-start.c:308)
==4970== 
--4970-- REDIR: 0x49f18e0 (libc.so.6:__memrchr_avx2) redirected to 0x48400d0 (memrchr)
==4970== Conditional jump or move depends on uninitialised value(s)
==4970==    at 0x5B9C43: PyMem_Realloc (in /usr/bin/python3.8)
==4970==    by 0x5EA784: PyList_Append (in /usr/bin/python3.8)
==4970==    by 0x54DFB2: ??? (in /usr/bin/python3.8)
==4970==    by 0x54DE1B: ??? (in /usr/bin/python3.8)
==4970==    by 0x54E312: ??? (in /usr/bin/python3.8)
==4970==    by 0x54DE61: ??? (in /usr/bin/python3.8)
==4970==    by 0x54E312: ??? (in /usr/bin/python3.8)
==4970==    by 0x6808F4: PyMarshal_ReadObjectFromString (in /usr/bin/python3.8)
==4970==    by 0x5C3A3F: ??? (in /usr/bin/python3.8)
==4970==    by 0x5F257C: PyVectorcall_Call (in /usr/bin/python3.8)
==4970==    by 0x56FCB5: _PyEval_EvalFrameDefault (in /usr/bin/python3.8)
==4970==    by 0x568229: _PyEval_EvalCodeWithName (in /usr/bin/python3.8)
==4970==  Uninitialised value was created by a heap allocation
==4970==    at 0x483B7F3: malloc (in /usr/lib/x86_64-linux-gnu/valgrind/vgpreload_memcheck-amd64-linux.so)
==4970==    by 0x53A797: _PyObject_GC_NewVar (in /usr/bin/python3.8)
==4970==    by 0x56907A: _PyEval_EvalCodeWithName (in /usr/bin/python3.8)
==4970==    by 0x5F6032: _PyFunction_Vectorcall (in /usr/bin/python3.8)
==4970==    by 0x569F5D: _PyEval_EvalFrameDefault (in /usr/bin/python3.8)
==4970==    by 0x5F5E55: _PyFunction_Vectorcall (in /usr/bin/python3.8)
==4970==    by 0x569F5D: _PyEval_EvalFrameDefault (in /usr/bin/python3.8)
==4970==    by 0x5F5E55: _PyFunction_Vectorcall (in /usr/bin/python3.8)
==4970==    by 0x5F3A10: ??? (in /usr/bin/python3.8)
==4970==    by 0x5F3E97: _PyObject_CallMethodIdObjArgs (in /usr/bin/python3.8)
==4970==    by 0x551492: PyImport_ImportModuleLevelObject (in /usr/bin/python3.8)
==4970==    by 0x56C1E2: _PyEval_EvalFrameDefault (in /usr/bin/python3.8)
==4970== 
==4970== Use of uninitialised value of size 8
==4970==    at 0x5B9C5B: PyMem_Realloc (in /usr/bin/python3.8)
==4970==    by 0x5EA784: PyList_Append (in /usr/bin/python3.8)
==4970==    by 0x54DFB2: ??? (in /usr/bin/python3.8)
==4970==    by 0x54DE1B: ??? (in /usr/bin/python3.8)
==4970==    by 0x54E312: ??? (in /usr/bin/python3.8)
==4970==    by 0x54DE61: ??? (in /usr/bin/python3.8)
==4970==    by 0x54E312: ??? (in /usr/bin/python3.8)
==4970==    by 0x6808F4: PyMarshal_ReadObjectFromString (in /usr/bin/python3.8)
==4970==    by 0x5C3A3F: ??? (in /usr/bin/python3.8)
==4970==    by 0x5F257C: PyVectorcall_Call (in /usr/bin/python3.8)
==4970==    by 0x56FCB5: _PyEval_EvalFrameDefault (in /usr/bin/python3.8)
==4970==    by 0x568229: _PyEval_EvalCodeWithName (in /usr/bin/python3.8)
==4970==  Uninitialised value was created by a heap allocation
==4970==    at 0x483B7F3: malloc (in /usr/lib/x86_64-linux-gnu/valgrind/vgpreload_memcheck-amd64-linux.so)
==4970==    by 0x53A797: _PyObject_GC_NewVar (in /usr/bin/python3.8)
==4970==    by 0x56907A: _PyEval_EvalCodeWithName (in /usr/bin/python3.8)
==4970==    by 0x5F6032: _PyFunction_Vectorcall (in /usr/bin/python3.8)
==4970==    by 0x569F5D: _PyEval_EvalFrameDefault (in /usr/bin/python3.8)
==4970==    by 0x5F5E55: _PyFunction_Vectorcall (in /usr/bin/python3.8)
==4970==    by 0x569F5D: _PyEval_EvalFrameDefault (in /usr/bin/python3.8)
==4970==    by 0x5F5E55: _PyFunction_Vectorcall (in /usr/bin/python3.8)
==4970==    by 0x5F3A10: ??? (in /usr/bin/python3.8)
==4970==    by 0x5F3E97: _PyObject_CallMethodIdObjArgs (in /usr/bin/python3.8)
==4970==    by 0x551492: PyImport_ImportModuleLevelObject (in /usr/bin/python3.8)
==4970==    by 0x56C1E2: _PyEval_EvalFrameDefault (in /usr/bin/python3.8)
==4970== 
==4970== Conditional jump or move depends on uninitialised value(s)
==4970==    at 0x5B9C43: PyMem_Realloc (in /usr/bin/python3.8)
==4970==    by 0x5EA784: PyList_Append (in /usr/bin/python3.8)
==4970==    by 0x54DC88: ??? (in /usr/bin/python3.8)
==4970==    by 0x54DE61: ??? (in /usr/bin/python3.8)
==4970==    by 0x54E328: ??? (in /usr/bin/python3.8)
==4970==    by 0x54DE61: ??? (in /usr/bin/python3.8)
==4970==    by 0x54E312: ??? (in /usr/bin/python3.8)
==4970==    by 0x6808F4: PyMarshal_ReadObjectFromString (in /usr/bin/python3.8)
==4970==    by 0x5C3A3F: ??? (in /usr/bin/python3.8)
==4970==    by 0x5F257C: PyVectorcall_Call (in /usr/bin/python3.8)
==4970==    by 0x56FCB5: _PyEval_EvalFrameDefault (in /usr/bin/python3.8)
==4970==    by 0x568229: _PyEval_EvalCodeWithName (in /usr/bin/python3.8)
==4970==  Uninitialised value was created by a heap allocation
==4970==    at 0x483B7F3: malloc (in /usr/lib/x86_64-linux-gnu/valgrind/vgpreload_memcheck-amd64-linux.so)
==4970==    by 0x53A797: _PyObject_GC_NewVar (in /usr/bin/python3.8)
==4970==    by 0x56907A: _PyEval_EvalCodeWithName (in /usr/bin/python3.8)
==4970==    by 0x5F6032: _PyFunction_Vectorcall (in /usr/bin/python3.8)
==4970==    by 0x569F5D: _PyEval_EvalFrameDefault (in /usr/bin/python3.8)
==4970==    by 0x5F5E55: _PyFunction_Vectorcall (in /usr/bin/python3.8)
==4970==    by 0x569F5D: _PyEval_EvalFrameDefault (in /usr/bin/python3.8)
==4970==    by 0x5F5E55: _PyFunction_Vectorcall (in /usr/bin/python3.8)
==4970==    by 0x5F3A10: ??? (in /usr/bin/python3.8)
==4970==    by 0x5F3E97: _PyObject_CallMethodIdObjArgs (in /usr/bin/python3.8)
==4970==    by 0x551492: PyImport_ImportModuleLevelObject (in /usr/bin/python3.8)
==4970==    by 0x56C1E2: _PyEval_EvalFrameDefault (in /usr/bin/python3.8)
==4970== 
==4970== Use of uninitialised value of size 8
==4970==    at 0x5B9C5B: PyMem_Realloc (in /usr/bin/python3.8)
==4970==    by 0x5EA784: PyList_Append (in /usr/bin/python3.8)
==4970==    by 0x54DC88: ??? (in /usr/bin/python3.8)
==4970==    by 0x54DE61: ??? (in /usr/bin/python3.8)
==4970==    by 0x54E328: ??? (in /usr/bin/python3.8)
==4970==    by 0x54DE61: ??? (in /usr/bin/python3.8)
==4970==    by 0x54E312: ??? (in /usr/bin/python3.8)
==4970==    by 0x6808F4: PyMarshal_ReadObjectFromString (in /usr/bin/python3.8)
==4970==    by 0x5C3A3F: ??? (in /usr/bin/python3.8)
==4970==    by 0x5F257C: PyVectorcall_Call (in /usr/bin/python3.8)
==4970==    by 0x56FCB5: _PyEval_EvalFrameDefault (in /usr/bin/python3.8)
==4970==    by 0x568229: _PyEval_EvalCodeWithName (in /usr/bin/python3.8)
==4970==  Uninitialised value was created by a heap allocation
==4970==    at 0x483B7F3: malloc (in /usr/lib/x86_64-linux-gnu/valgrind/vgpreload_memcheck-amd64-linux.so)
==4970==    by 0x53A797: _PyObject_GC_NewVar (in /usr/bin/python3.8)
==4970==    by 0x56907A: _PyEval_EvalCodeWithName (in /usr/bin/python3.8)
==4970==    by 0x5F6032: _PyFunction_Vectorcall (in /usr/bin/python3.8)
==4970==    by 0x569F5D: _PyEval_EvalFrameDefault (in /usr/bin/python3.8)
==4970==    by 0x5F5E55: _PyFunction_Vectorcall (in /usr/bin/python3.8)
==4970==    by 0x569F5D: _PyEval_EvalFrameDefault (in /usr/bin/python3.8)
==4970==    by 0x5F5E55: _PyFunction_Vectorcall (in /usr/bin/python3.8)
==4970==    by 0x5F3A10: ??? (in /usr/bin/python3.8)
==4970==    by 0x5F3E97: _PyObject_CallMethodIdObjArgs (in /usr/bin/python3.8)
==4970==    by 0x551492: PyImport_ImportModuleLevelObject (in /usr/bin/python3.8)
==4970==    by 0x56C1E2: _PyEval_EvalFrameDefault (in /usr/bin/python3.8)
==4970== 
==4970== Invalid read of size 4
==4970==    at 0x5B9C3A: PyMem_Realloc (in /usr/bin/python3.8)
==4970==    by 0x5EA784: PyList_Append (in /usr/bin/python3.8)
==4970==    by 0x54DC88: ??? (in /usr/bin/python3.8)
==4970==    by 0x54DD5C: ??? (in /usr/bin/python3.8)
==4970==    by 0x54E328: ??? (in /usr/bin/python3.8)
==4970==    by 0x54DE61: ??? (in /usr/bin/python3.8)
==4970==    by 0x54E312: ??? (in /usr/bin/python3.8)
==4970==    by 0x6808F4: PyMarshal_ReadObjectFromString (in /usr/bin/python3.8)
==4970==    by 0x5C3A3F: ??? (in /usr/bin/python3.8)
==4970==    by 0x5F257C: PyVectorcall_Call (in /usr/bin/python3.8)
==4970==    by 0x56FCB5: _PyEval_EvalFrameDefault (in /usr/bin/python3.8)
==4970==    by 0x568229: _PyEval_EvalCodeWithName (in /usr/bin/python3.8)
==4970==  Address 0x4c67020 is 512 bytes inside a block of size 704 free'd
==4970==    at 0x483DFAF: realloc (in /usr/lib/x86_64-linux-gnu/valgrind/vgpreload_memcheck-amd64-linux.so)
==4970==    by 0x5EA784: PyList_Append (in /usr/bin/python3.8)
==4970==    by 0x54DC88: ??? (in /usr/bin/python3.8)
==4970==    by 0x54DE61: ??? (in /usr/bin/python3.8)
==4970==    by 0x54E328: ??? (in /usr/bin/python3.8)
==4970==    by 0x54DE61: ??? (in /usr/bin/python3.8)
==4970==    by 0x54E312: ??? (in /usr/bin/python3.8)
==4970==    by 0x6808F4: PyMarshal_ReadObjectFromString (in /usr/bin/python3.8)
==4970==    by 0x5C3A3F: ??? (in /usr/bin/python3.8)
==4970==    by 0x5F257C: PyVectorcall_Call (in /usr/bin/python3.8)
==4970==    by 0x56FCB5: _PyEval_EvalFrameDefault (in /usr/bin/python3.8)
==4970==    by 0x568229: _PyEval_EvalCodeWithName (in /usr/bin/python3.8)
==4970==  Block was alloc'd at
==4970==    at 0x483DFAF: realloc (in /usr/lib/x86_64-linux-gnu/valgrind/vgpreload_memcheck-amd64-linux.so)
==4970==    by 0x5EA784: PyList_Append (in /usr/bin/python3.8)
==4970==    by 0x54DFB2: ??? (in /usr/bin/python3.8)
==4970==    by 0x54DE1B: ??? (in /usr/bin/python3.8)
==4970==    by 0x54E312: ??? (in /usr/bin/python3.8)
==4970==    by 0x54DE61: ??? (in /usr/bin/python3.8)
==4970==    by 0x54E312: ??? (in /usr/bin/python3.8)
==4970==    by 0x6808F4: PyMarshal_ReadObjectFromString (in /usr/bin/python3.8)
==4970==    by 0x5C3A3F: ??? (in /usr/bin/python3.8)
==4970==    by 0x5F257C: PyVectorcall_Call (in /usr/bin/python3.8)
==4970==    by 0x56FCB5: _PyEval_EvalFrameDefault (in /usr/bin/python3.8)
==4970==    by 0x568229: _PyEval_EvalCodeWithName (in /usr/bin/python3.8)
==4970== 
==4970== Invalid read of size 4
==4970==    at 0x5B9C3A: PyMem_Realloc (in /usr/bin/python3.8)
==4970==    by 0x5EA784: PyList_Append (in /usr/bin/python3.8)
==4970==    by 0x54DFB2: ??? (in /usr/bin/python3.8)
==4970==    by 0x54DE61: ??? (in /usr/bin/python3.8)
==4970==    by 0x54E312: ??? (in /usr/bin/python3.8)
==4970==    by 0x54DE61: ??? (in /usr/bin/python3.8)
==4970==    by 0x54E312: ??? (in /usr/bin/python3.8)
==4970==    by 0x6808F4: PyMarshal_ReadObjectFromString (in /usr/bin/python3.8)
==4970==    by 0x5C3A3F: ??? (in /usr/bin/python3.8)
==4970==    by 0x5F257C: PyVectorcall_Call (in /usr/bin/python3.8)
==4970==    by 0x56FCB5: _PyEval_EvalFrameDefault (in /usr/bin/python3.8)
==4970==    by 0x568229: _PyEval_EvalCodeWithName (in /usr/bin/python3.8)
==4970==  Address 0x4c67020 is 512 bytes inside a block of size 704 free'd
==4970==    at 0x483DFAF: realloc (in /usr/lib/x86_64-linux-gnu/valgrind/vgpreload_memcheck-amd64-linux.so)
==4970==    by 0x5EA784: PyList_Append (in /usr/bin/python3.8)
==4970==    by 0x54DC88: ??? (in /usr/bin/python3.8)
==4970==    by 0x54DE61: ??? (in /usr/bin/python3.8)
==4970==    by 0x54E328: ??? (in /usr/bin/python3.8)
==4970==    by 0x54DE61: ??? (in /usr/bin/python3.8)
==4970==    by 0x54E312: ??? (in /usr/bin/python3.8)
==4970==    by 0x6808F4: PyMarshal_ReadObjectFromString (in /usr/bin/python3.8)
==4970==    by 0x5C3A3F: ??? (in /usr/bin/python3.8)
==4970==    by 0x5F257C: PyVectorcall_Call (in /usr/bin/python3.8)
==4970==    by 0x56FCB5: _PyEval_EvalFrameDefault (in /usr/bin/python3.8)
==4970==    by 0x568229: _PyEval_EvalCodeWithName (in /usr/bin/python3.8)
==4970==  Block was alloc'd at
==4970==    at 0x483DFAF: realloc (in /usr/lib/x86_64-linux-gnu/valgrind/vgpreload_memcheck-amd64-linux.so)
==4970==    by 0x5EA784: PyList_Append (in /usr/bin/python3.8)
==4970==    by 0x54DFB2: ??? (in /usr/bin/python3.8)
==4970==    by 0x54DE1B: ??? (in /usr/bin/python3.8)
==4970==    by 0x54E312: ??? (in /usr/bin/python3.8)
==4970==    by 0x54DE61: ??? (in /usr/bin/python3.8)
==4970==    by 0x54E312: ??? (in /usr/bin/python3.8)
==4970==    by 0x6808F4: PyMarshal_ReadObjectFromString (in /usr/bin/python3.8)
==4970==    by 0x5C3A3F: ??? (in /usr/bin/python3.8)
==4970==    by 0x5F257C: PyVectorcall_Call (in /usr/bin/python3.8)
==4970==    by 0x56FCB5: _PyEval_EvalFrameDefault (in /usr/bin/python3.8)
==4970==    by 0x568229: _PyEval_EvalCodeWithName (in /usr/bin/python3.8)
==4970== 
==4970== Invalid read of size 4
==4970==    at 0x5B9C3A: PyMem_Realloc (in /usr/bin/python3.8)
==4970==    by 0x5EA784: PyList_Append (in /usr/bin/python3.8)
==4970==    by 0x54DC88: ??? (in /usr/bin/python3.8)
==4970==    by 0x54DD0E: ??? (in /usr/bin/python3.8)
==4970==    by 0x54DD35: ??? (in /usr/bin/python3.8)
==4970==    by 0x54E312: ??? (in /usr/bin/python3.8)
==4970==    by 0x54DDAA: ??? (in /usr/bin/python3.8)
==4970==    by 0x54E312: ??? (in /usr/bin/python3.8)
==4970==    by 0x54DE61: ??? (in /usr/bin/python3.8)
==4970==    by 0x54E312: ??? (in /usr/bin/python3.8)
==4970==    by 0x6808F4: PyMarshal_ReadObjectFromString (in /usr/bin/python3.8)
==4970==    by 0x5C3A3F: ??? (in /usr/bin/python3.8)
==4970==  Address 0x4c69020 is 1,264 bytes inside a block of size 1,608 free'd
==4970==    at 0x483DFAF: realloc (in /usr/lib/x86_64-linux-gnu/valgrind/vgpreload_memcheck-amd64-linux.so)
==4970==    by 0x5EA784: PyList_Append (in /usr/bin/python3.8)
==4970==    by 0x54DC88: ??? (in /usr/bin/python3.8)
==4970==    by 0x54E394: ??? (in /usr/bin/python3.8)
==4970==    by 0x54DE1B: ??? (in /usr/bin/python3.8)
==4970==    by 0x54E312: ??? (in /usr/bin/python3.8)
==4970==    by 0x54DE61: ??? (in /usr/bin/python3.8)
==4970==    by 0x54E312: ??? (in /usr/bin/python3.8)
==4970==    by 0x6808F4: PyMarshal_ReadObjectFromString (in /usr/bin/python3.8)
==4970==    by 0x5C3A3F: ??? (in /usr/bin/python3.8)
==4970==    by 0x5F257C: PyVectorcall_Call (in /usr/bin/python3.8)
==4970==    by 0x56FCB5: _PyEval_EvalFrameDefault (in /usr/bin/python3.8)
==4970==  Block was alloc'd at
==4970==    at 0x483DFAF: realloc (in /usr/lib/x86_64-linux-gnu/valgrind/vgpreload_memcheck-amd64-linux.so)
==4970==    by 0x5EA784: PyList_Append (in /usr/bin/python3.8)
==4970==    by 0x54DC88: ??? (in /usr/bin/python3.8)
==4970==    by 0x54DD0E: ??? (in /usr/bin/python3.8)
==4970==    by 0x54E328: ??? (in /usr/bin/python3.8)
==4970==    by 0x54DE61: ??? (in /usr/bin/python3.8)
==4970==    by 0x54E312: ??? (in /usr/bin/python3.8)
==4970==    by 0x6808F4: PyMarshal_ReadObjectFromString (in /usr/bin/python3.8)
==4970==    by 0x5C3A3F: ??? (in /usr/bin/python3.8)
==4970==    by 0x5F257C: PyVectorcall_Call (in /usr/bin/python3.8)
==4970==    by 0x56FCB5: _PyEval_EvalFrameDefault (in /usr/bin/python3.8)
==4970==    by 0x568229: _PyEval_EvalCodeWithName (in /usr/bin/python3.8)
==4970== 
==4970== Invalid read of size 4
==4970==    at 0x5EB64C: ??? (in /usr/bin/python3.8)
==4970==    by 0x680907: PyMarshal_ReadObjectFromString (in /usr/bin/python3.8)
==4970==    by 0x5C3A3F: ??? (in /usr/bin/python3.8)
==4970==    by 0x5F257C: PyVectorcall_Call (in /usr/bin/python3.8)
==4970==    by 0x56FCB5: _PyEval_EvalFrameDefault (in /usr/bin/python3.8)
==4970==    by 0x568229: _PyEval_EvalCodeWithName (in /usr/bin/python3.8)
==4970==    by 0x5F6032: _PyFunction_Vectorcall (in /usr/bin/python3.8)
==4970==    by 0x569F5D: _PyEval_EvalFrameDefault (in /usr/bin/python3.8)
==4970==    by 0x5F5E55: _PyFunction_Vectorcall (in /usr/bin/python3.8)
==4970==    by 0x56EF96: _PyEval_EvalFrameDefault (in /usr/bin/python3.8)
==4970==    by 0x5F5E55: _PyFunction_Vectorcall (in /usr/bin/python3.8)
==4970==    by 0x569F5D: _PyEval_EvalFrameDefault (in /usr/bin/python3.8)
==4970==  Address 0x4c6a020 is 1,744 bytes inside a block of size 2,152 free'd
==4970==    at 0x483DFAF: realloc (in /usr/lib/x86_64-linux-gnu/valgrind/vgpreload_memcheck-amd64-linux.so)
==4970==    by 0x5EA784: PyList_Append (in /usr/bin/python3.8)
==4970==    by 0x54DC88: ??? (in /usr/bin/python3.8)
==4970==    by 0x54DD0E: ??? (in /usr/bin/python3.8)
==4970==    by 0x54DD35: ??? (in /usr/bin/python3.8)
==4970==    by 0x54E312: ??? (in /usr/bin/python3.8)
==4970==    by 0x54DDAA: ??? (in /usr/bin/python3.8)
==4970==    by 0x54E312: ??? (in /usr/bin/python3.8)
==4970==    by 0x54DE61: ??? (in /usr/bin/python3.8)
==4970==    by 0x54E312: ??? (in /usr/bin/python3.8)
==4970==    by 0x6808F4: PyMarshal_ReadObjectFromString (in /usr/bin/python3.8)
==4970==    by 0x5C3A3F: ??? (in /usr/bin/python3.8)
==4970==  Block was alloc'd at
==4970==    at 0x483DFAF: realloc (in /usr/lib/x86_64-linux-gnu/valgrind/vgpreload_memcheck-amd64-linux.so)
==4970==    by 0x5EA784: PyList_Append (in /usr/bin/python3.8)
==4970==    by 0x54DC88: ??? (in /usr/bin/python3.8)
==4970==    by 0x54DD5C: ??? (in /usr/bin/python3.8)
==4970==    by 0x54E328: ??? (in /usr/bin/python3.8)
==4970==    by 0x54DE61: ??? (in /usr/bin/python3.8)
==4970==    by 0x54E312: ??? (in /usr/bin/python3.8)
==4970==    by 0x54DE61: ??? (in /usr/bin/python3.8)
==4970==    by 0x54E312: ??? (in /usr/bin/python3.8)
==4970==    by 0x6808F4: PyMarshal_ReadObjectFromString (in /usr/bin/python3.8)
==4970==    by 0x5C3A3F: ??? (in /usr/bin/python3.8)
==4970==    by 0x5F257C: PyVectorcall_Call (in /usr/bin/python3.8)
==4970== 
==4970== Invalid read of size 4
==4970==    at 0x5B8222: PyObject_Free (in /usr/bin/python3.8)
==4970==    by 0x5D1AEB: ??? (in /usr/bin/python3.8)
==4970==    by 0x5A785F: ??? (in /usr/bin/python3.8)
==4970==    by 0x5F3332: _PyObject_MakeTpCall (in /usr/bin/python3.8)
==4970==    by 0x4F735F: ??? (in /usr/bin/python3.8)
==4970==    by 0x5C3B96: ??? (in /usr/bin/python3.8)
==4970==    by 0x569F5D: _PyEval_EvalFrameDefault (in /usr/bin/python3.8)
==4970==    by 0x568229: _PyEval_EvalCodeWithName (in /usr/bin/python3.8)
==4970==    by 0x68C1E6: PyEval_EvalCode (in /usr/bin/python3.8)
==4970==    by 0x5FF1F3: ??? (in /usr/bin/python3.8)
==4970==    by 0x5C3CAF: ??? (in /usr/bin/python3.8)
==4970==    by 0x569F5D: _PyEval_EvalFrameDefault (in /usr/bin/python3.8)
==4970==  Address 0x4c6f020 is 16 bytes after a block of size 944 in arena "client"
==4970== 
==4970== Invalid read of size 4
==4970==    at 0x5B8222: PyObject_Free (in /usr/bin/python3.8)
==4970==    by 0x5D1AEB: ??? (in /usr/bin/python3.8)
==4970==    by 0x4F6871: ??? (in /usr/bin/python3.8)
==4970==    by 0x5C3B96: ??? (in /usr/bin/python3.8)
==4970==    by 0x569F5D: _PyEval_EvalFrameDefault (in /usr/bin/python3.8)
==4970==    by 0x568229: _PyEval_EvalCodeWithName (in /usr/bin/python3.8)
==4970==    by 0x68C1E6: PyEval_EvalCode (in /usr/bin/python3.8)
==4970==    by 0x5FF1F3: ??? (in /usr/bin/python3.8)
==4970==    by 0x5C3CAF: ??? (in /usr/bin/python3.8)
==4970==    by 0x569F5D: _PyEval_EvalFrameDefault (in /usr/bin/python3.8)
==4970==    by 0x5F5E55: _PyFunction_Vectorcall (in /usr/bin/python3.8)
==4970==    by 0x56EF96: _PyEval_EvalFrameDefault (in /usr/bin/python3.8)
==4970==  Address 0x4c6f020 is 16 bytes after a block of size 944 in arena "client"
==4970== 
==4970== Conditional jump or move depends on uninitialised value(s)
==4970==    at 0x59C1BC: ??? (in /usr/bin/python3.8)
==4970==    by 0x506055: ??? (in /usr/bin/python3.8)
==4970==    by 0x5EBBD7: ??? (in /usr/bin/python3.8)
==4970==    by 0x5F5E8C: _PyFunction_Vectorcall (in /usr/bin/python3.8)
==4970==    by 0x56EF96: _PyEval_EvalFrameDefault (in /usr/bin/python3.8)
==4970==    by 0x5F5E55: _PyFunction_Vectorcall (in /usr/bin/python3.8)
==4970==    by 0x569F5D: _PyEval_EvalFrameDefault (in /usr/bin/python3.8)
==4970==    by 0x5F5E55: _PyFunction_Vectorcall (in /usr/bin/python3.8)
==4970==    by 0x569F5D: _PyEval_EvalFrameDefault (in /usr/bin/python3.8)
==4970==    by 0x5F5E55: _PyFunction_Vectorcall (in /usr/bin/python3.8)
==4970==    by 0x5F3A10: ??? (in /usr/bin/python3.8)
==4970==    by 0x5F3E97: _PyObject_CallMethodIdObjArgs (in /usr/bin/python3.8)
==4970==  Uninitialised value was created by a heap allocation
==4970==    at 0x483B7F3: malloc (in /usr/lib/x86_64-linux-gnu/valgrind/vgpreload_memcheck-amd64-linux.so)
==4970==    by 0x53A797: _PyObject_GC_NewVar (in /usr/bin/python3.8)
==4970==    by 0x56907A: _PyEval_EvalCodeWithName (in /usr/bin/python3.8)
==4970==    by 0x5F6032: _PyFunction_Vectorcall (in /usr/bin/python3.8)
==4970==    by 0x569F5D: _PyEval_EvalFrameDefault (in /usr/bin/python3.8)
==4970==    by 0x5F5E55: _PyFunction_Vectorcall (in /usr/bin/python3.8)
==4970==    by 0x569F5D: _PyEval_EvalFrameDefault (in /usr/bin/python3.8)
==4970==    by 0x5F5E55: _PyFunction_Vectorcall (in /usr/bin/python3.8)
==4970==    by 0x5F3A10: ??? (in /usr/bin/python3.8)
==4970==    by 0x5F3E97: _PyObject_CallMethodIdObjArgs (in /usr/bin/python3.8)
==4970==    by 0x551492: PyImport_ImportModuleLevelObject (in /usr/bin/python3.8)
==4970==    by 0x56C1E2: _PyEval_EvalFrameDefault (in /usr/bin/python3.8)
==4970== 
==4970== Use of uninitialised value of size 8
==4970==    at 0x59C1D4: ??? (in /usr/bin/python3.8)
==4970==    by 0x506055: ??? (in /usr/bin/python3.8)
==4970==    by 0x5EBBD7: ??? (in /usr/bin/python3.8)
==4970==    by 0x5F5E8C: _PyFunction_Vectorcall (in /usr/bin/python3.8)
==4970==    by 0x56EF96: _PyEval_EvalFrameDefault (in /usr/bin/python3.8)
==4970==    by 0x5F5E55: _PyFunction_Vectorcall (in /usr/bin/python3.8)
==4970==    by 0x569F5D: _PyEval_EvalFrameDefault (in /usr/bin/python3.8)
==4970==    by 0x5F5E55: _PyFunction_Vectorcall (in /usr/bin/python3.8)
==4970==    by 0x569F5D: _PyEval_EvalFrameDefault (in /usr/bin/python3.8)
==4970==    by 0x5F5E55: _PyFunction_Vectorcall (in /usr/bin/python3.8)
==4970==    by 0x5F3A10: ??? (in /usr/bin/python3.8)
==4970==    by 0x5F3E97: _PyObject_CallMethodIdObjArgs (in /usr/bin/python3.8)
==4970==  Uninitialised value was created by a heap allocation
==4970==    at 0x483B7F3: malloc (in /usr/lib/x86_64-linux-gnu/valgrind/vgpreload_memcheck-amd64-linux.so)
==4970==    by 0x53A797: _PyObject_GC_NewVar (in /usr/bin/python3.8)
==4970==    by 0x56907A: _PyEval_EvalCodeWithName (in /usr/bin/python3.8)
==4970==    by 0x5F6032: _PyFunction_Vectorcall (in /usr/bin/python3.8)
==4970==    by 0x569F5D: _PyEval_EvalFrameDefault (in /usr/bin/python3.8)
==4970==    by 0x5F5E55: _PyFunction_Vectorcall (in /usr/bin/python3.8)
==4970==    by 0x569F5D: _PyEval_EvalFrameDefault (in /usr/bin/python3.8)
==4970==    by 0x5F5E55: _PyFunction_Vectorcall (in /usr/bin/python3.8)
==4970==    by 0x5F3A10: ??? (in /usr/bin/python3.8)
==4970==    by 0x5F3E97: _PyObject_CallMethodIdObjArgs (in /usr/bin/python3.8)
==4970==    by 0x551492: PyImport_ImportModuleLevelObject (in /usr/bin/python3.8)
==4970==    by 0x56C1E2: _PyEval_EvalFrameDefault (in /usr/bin/python3.8)
==4970== 
==4970== Conditional jump or move depends on uninitialised value(s)
==4970==    at 0x5B822C: PyObject_Free (in /usr/bin/python3.8)
==4970==    by 0x5ADAD8: ??? (in /usr/bin/python3.8)
==4970==    by 0x50606B: ??? (in /usr/bin/python3.8)
==4970==    by 0x5EBBD7: ??? (in /usr/bin/python3.8)
==4970==    by 0x5F5E8C: _PyFunction_Vectorcall (in /usr/bin/python3.8)
==4970==    by 0x56EF96: _PyEval_EvalFrameDefault (in /usr/bin/python3.8)
==4970==    by 0x5F5E55: _PyFunction_Vectorcall (in /usr/bin/python3.8)
==4970==    by 0x569F5D: _PyEval_EvalFrameDefault (in /usr/bin/python3.8)
==4970==    by 0x5F5E55: _PyFunction_Vectorcall (in /usr/bin/python3.8)
==4970==    by 0x569F5D: _PyEval_EvalFrameDefault (in /usr/bin/python3.8)
==4970==    by 0x5F5E55: _PyFunction_Vectorcall (in /usr/bin/python3.8)
==4970==    by 0x5F3A10: ??? (in /usr/bin/python3.8)
==4970==  Uninitialised value was created by a heap allocation
==4970==    at 0x483B7F3: malloc (in /usr/lib/x86_64-linux-gnu/valgrind/vgpreload_memcheck-amd64-linux.so)
==4970==    by 0x53A797: _PyObject_GC_NewVar (in /usr/bin/python3.8)
==4970==    by 0x56907A: _PyEval_EvalCodeWithName (in /usr/bin/python3.8)
==4970==    by 0x5F6032: _PyFunction_Vectorcall (in /usr/bin/python3.8)
==4970==    by 0x569F5D: _PyEval_EvalFrameDefault (in /usr/bin/python3.8)
==4970==    by 0x5F5E55: _PyFunction_Vectorcall (in /usr/bin/python3.8)
==4970==    by 0x569F5D: _PyEval_EvalFrameDefault (in /usr/bin/python3.8)
==4970==    by 0x5F5E55: _PyFunction_Vectorcall (in /usr/bin/python3.8)
==4970==    by 0x5F3A10: ??? (in /usr/bin/python3.8)
==4970==    by 0x5F3E97: _PyObject_CallMethodIdObjArgs (in /usr/bin/python3.8)
==4970==    by 0x551492: PyImport_ImportModuleLevelObject (in /usr/bin/python3.8)
==4970==    by 0x56C1E2: _PyEval_EvalFrameDefault (in /usr/bin/python3.8)
==4970== 
==4970== Use of uninitialised value of size 8
==4970==    at 0x5B8244: PyObject_Free (in /usr/bin/python3.8)
==4970==    by 0x5ADAD8: ??? (in /usr/bin/python3.8)
==4970==    by 0x50606B: ??? (in /usr/bin/python3.8)
==4970==    by 0x5EBBD7: ??? (in /usr/bin/python3.8)
==4970==    by 0x5F5E8C: _PyFunction_Vectorcall (in /usr/bin/python3.8)
==4970==    by 0x56EF96: _PyEval_EvalFrameDefault (in /usr/bin/python3.8)
==4970==    by 0x5F5E55: _PyFunction_Vectorcall (in /usr/bin/python3.8)
==4970==    by 0x569F5D: _PyEval_EvalFrameDefault (in /usr/bin/python3.8)
==4970==    by 0x5F5E55: _PyFunction_Vectorcall (in /usr/bin/python3.8)
==4970==    by 0x569F5D: _PyEval_EvalFrameDefault (in /usr/bin/python3.8)
==4970==    by 0x5F5E55: _PyFunction_Vectorcall (in /usr/bin/python3.8)
==4970==    by 0x5F3A10: ??? (in /usr/bin/python3.8)
==4970==  Uninitialised value was created by a heap allocation
==4970==    at 0x483B7F3: malloc (in /usr/lib/x86_64-linux-gnu/valgrind/vgpreload_memcheck-amd64-linux.so)
==4970==    by 0x53A797: _PyObject_GC_NewVar (in /usr/bin/python3.8)
==4970==    by 0x56907A: _PyEval_EvalCodeWithName (in /usr/bin/python3.8)
==4970==    by 0x5F6032: _PyFunction_Vectorcall (in /usr/bin/python3.8)
==4970==    by 0x569F5D: _PyEval_EvalFrameDefault (in /usr/bin/python3.8)
==4970==    by 0x5F5E55: _PyFunction_Vectorcall (in /usr/bin/python3.8)
==4970==    by 0x569F5D: _PyEval_EvalFrameDefault (in /usr/bin/python3.8)
==4970==    by 0x5F5E55: _PyFunction_Vectorcall (in /usr/bin/python3.8)
==4970==    by 0x5F3A10: ??? (in /usr/bin/python3.8)
==4970==    by 0x5F3E97: _PyObject_CallMethodIdObjArgs (in /usr/bin/python3.8)
==4970==    by 0x551492: PyImport_ImportModuleLevelObject (in /usr/bin/python3.8)
==4970==    by 0x56C1E2: _PyEval_EvalFrameDefault (in /usr/bin/python3.8)
==4970== 
==4970== Invalid read of size 4
==4970==    at 0x5B8222: PyObject_Free (in /usr/bin/python3.8)
==4970==    by 0x5ADAD8: ??? (in /usr/bin/python3.8)
==4970==    by 0x506081: ??? (in /usr/bin/python3.8)
==4970==    by 0x5EBBD7: ??? (in /usr/bin/python3.8)
==4970==    by 0x5F5E8C: _PyFunction_Vectorcall (in /usr/bin/python3.8)
==4970==    by 0x56EF96: _PyEval_EvalFrameDefault (in /usr/bin/python3.8)
==4970==    by 0x5F5E55: _PyFunction_Vectorcall (in /usr/bin/python3.8)
==4970==    by 0x569F5D: _PyEval_EvalFrameDefault (in /usr/bin/python3.8)
==4970==    by 0x5F5E55: _PyFunction_Vectorcall (in /usr/bin/python3.8)
==4970==    by 0x569F5D: _PyEval_EvalFrameDefault (in /usr/bin/python3.8)
==4970==    by 0x5F5E55: _PyFunction_Vectorcall (in /usr/bin/python3.8)
==4970==    by 0x5F3A10: ??? (in /usr/bin/python3.8)
==4970==  Address 0x4c6b020 is 416 bytes inside a block of size 2,832 free'd
==4970==    at 0x483CA3F: free (in /usr/lib/x86_64-linux-gnu/valgrind/vgpreload_memcheck-amd64-linux.so)
==4970==    by 0x5EB98C: ??? (in /usr/bin/python3.8)
==4970==    by 0x680907: PyMarshal_ReadObjectFromString (in /usr/bin/python3.8)
==4970==    by 0x5C3A3F: ??? (in /usr/bin/python3.8)
==4970==    by 0x5F257C: PyVectorcall_Call (in /usr/bin/python3.8)
==4970==    by 0x56FCB5: _PyEval_EvalFrameDefault (in /usr/bin/python3.8)
==4970==    by 0x568229: _PyEval_EvalCodeWithName (in /usr/bin/python3.8)
==4970==    by 0x5F6032: _PyFunction_Vectorcall (in /usr/bin/python3.8)
==4970==    by 0x569F5D: _PyEval_EvalFrameDefault (in /usr/bin/python3.8)
==4970==    by 0x5F5E55: _PyFunction_Vectorcall (in /usr/bin/python3.8)
==4970==    by 0x56EF96: _PyEval_EvalFrameDefault (in /usr/bin/python3.8)
==4970==    by 0x5F5E55: _PyFunction_Vectorcall (in /usr/bin/python3.8)
==4970==  Block was alloc'd at
==4970==    at 0x483DFAF: realloc (in /usr/lib/x86_64-linux-gnu/valgrind/vgpreload_memcheck-amd64-linux.so)
==4970==    by 0x5EA784: PyList_Append (in /usr/bin/python3.8)
==4970==    by 0x54DC88: ??? (in /usr/bin/python3.8)
==4970==    by 0x54E394: ??? (in /usr/bin/python3.8)
==4970==    by 0x54DDAA: ??? (in /usr/bin/python3.8)
==4970==    by 0x54E312: ??? (in /usr/bin/python3.8)
==4970==    by 0x54DE61: ??? (in /usr/bin/python3.8)
==4970==    by 0x54E312: ??? (in /usr/bin/python3.8)
==4970==    by 0x6808F4: PyMarshal_ReadObjectFromString (in /usr/bin/python3.8)
==4970==    by 0x5C3A3F: ??? (in /usr/bin/python3.8)
==4970==    by 0x5F257C: PyVectorcall_Call (in /usr/bin/python3.8)
==4970==    by 0x56FCB5: _PyEval_EvalFrameDefault (in /usr/bin/python3.8)
==4970== 
==4970== Invalid read of size 4
==4970==    at 0x5B8222: PyObject_Free (in /usr/bin/python3.8)
==4970==    by 0x5CDC77: ??? (in /usr/bin/python3.8)
==4970==    by 0x5CEEEF: PyDict_SetItem (in /usr/bin/python3.8)
==4970==    by 0x5BFE1F: PyObject_SetAttr (in /usr/bin/python3.8)
==4970==    by 0x5C235C: ??? (in /usr/bin/python3.8)
==4970==    by 0x6A55B1: PyModule_AddFunctions (in /usr/bin/python3.8)
==4970==    by 0x6A5829: _PyModule_CreateInitialized (in /usr/bin/python3.8)
==4970==    by 0x639ECD: PyInit_posix (in /usr/bin/python3.8)
==4970==    by 0x5524A9: ??? (in /usr/bin/python3.8)
==4970==    by 0x5C3A3F: ??? (in /usr/bin/python3.8)
==4970==    by 0x5F257C: PyVectorcall_Call (in /usr/bin/python3.8)
==4970==    by 0x56FCB5: _PyEval_EvalFrameDefault (in /usr/bin/python3.8)
==4970==  Address 0x4c79020 is 736 bytes inside a block of size 1,112 free'd
==4970==    at 0x483CA3F: free (in /usr/lib/x86_64-linux-gnu/valgrind/vgpreload_memcheck-amd64-linux.so)
==4970==    by 0x5CDC77: ??? (in /usr/bin/python3.8)
==4970==    by 0x5CEEEF: PyDict_SetItem (in /usr/bin/python3.8)
==4970==    by 0x5BFE1F: PyObject_SetAttr (in /usr/bin/python3.8)
==4970==    by 0x5C235C: ??? (in /usr/bin/python3.8)
==4970==    by 0x6A55B1: PyModule_AddFunctions (in /usr/bin/python3.8)
==4970==    by 0x6A5829: _PyModule_CreateInitialized (in /usr/bin/python3.8)
==4970==    by 0x639ECD: PyInit_posix (in /usr/bin/python3.8)
==4970==    by 0x5524A9: ??? (in /usr/bin/python3.8)
==4970==    by 0x5C3A3F: ??? (in /usr/bin/python3.8)
==4970==    by 0x5F257C: PyVectorcall_Call (in /usr/bin/python3.8)
==4970==    by 0x56FCB5: _PyEval_EvalFrameDefault (in /usr/bin/python3.8)
==4970==  Block was alloc'd at
==4970==    at 0x483B7F3: malloc (in /usr/lib/x86_64-linux-gnu/valgrind/vgpreload_memcheck-amd64-linux.so)
==4970==    by 0x5B8F63: PyObject_Malloc (in /usr/bin/python3.8)
==4970==    by 0x5CDC05: ??? (in /usr/bin/python3.8)
==4970==    by 0x5CEEEF: PyDict_SetItem (in /usr/bin/python3.8)
==4970==    by 0x5BFE1F: PyObject_SetAttr (in /usr/bin/python3.8)
==4970==    by 0x5C235C: ??? (in /usr/bin/python3.8)
==4970==    by 0x6A55B1: PyModule_AddFunctions (in /usr/bin/python3.8)
==4970==    by 0x6A5829: _PyModule_CreateInitialized (in /usr/bin/python3.8)
==4970==    by 0x639ECD: PyInit_posix (in /usr/bin/python3.8)
==4970==    by 0x5524A9: ??? (in /usr/bin/python3.8)
==4970==    by 0x5C3A3F: ??? (in /usr/bin/python3.8)
==4970==    by 0x5F257C: PyVectorcall_Call (in /usr/bin/python3.8)
==4970== 
==4970== Invalid read of size 4
==4970==    at 0x5B8222: PyObject_Free (in /usr/bin/python3.8)
==4970==    by 0x5CDC77: ??? (in /usr/bin/python3.8)
==4970==    by 0x54A5F5: PyModule_AddIntConstant (in /usr/bin/python3.8)
==4970==    by 0x63A0C2: PyInit_posix (in /usr/bin/python3.8)
==4970==    by 0x5524A9: ??? (in /usr/bin/python3.8)
==4970==    by 0x5C3A3F: ??? (in /usr/bin/python3.8)
==4970==    by 0x5F257C: PyVectorcall_Call (in /usr/bin/python3.8)
==4970==    by 0x56FCB5: _PyEval_EvalFrameDefault (in /usr/bin/python3.8)
==4970==    by 0x568229: _PyEval_EvalCodeWithName (in /usr/bin/python3.8)
==4970==    by 0x5F6032: _PyFunction_Vectorcall (in /usr/bin/python3.8)
==4970==    by 0x569F5D: _PyEval_EvalFrameDefault (in /usr/bin/python3.8)
==4970==    by 0x50A23D: ??? (in /usr/bin/python3.8)
==4970==  Address 0x4c79020 is 736 bytes inside a block of size 1,112 free'd
==4970==    at 0x483CA3F: free (in /usr/lib/x86_64-linux-gnu/valgrind/vgpreload_memcheck-amd64-linux.so)
==4970==    by 0x5CDC77: ??? (in /usr/bin/python3.8)
==4970==    by 0x5CEEEF: PyDict_SetItem (in /usr/bin/python3.8)
==4970==    by 0x5BFE1F: PyObject_SetAttr (in /usr/bin/python3.8)
==4970==    by 0x5C235C: ??? (in /usr/bin/python3.8)
==4970==    by 0x6A55B1: PyModule_AddFunctions (in /usr/bin/python3.8)
==4970==    by 0x6A5829: _PyModule_CreateInitialized (in /usr/bin/python3.8)
==4970==    by 0x639ECD: PyInit_posix (in /usr/bin/python3.8)
==4970==    by 0x5524A9: ??? (in /usr/bin/python3.8)
==4970==    by 0x5C3A3F: ??? (in /usr/bin/python3.8)
==4970==    by 0x5F257C: PyVectorcall_Call (in /usr/bin/python3.8)
==4970==    by 0x56FCB5: _PyEval_EvalFrameDefault (in /usr/bin/python3.8)
==4970==  Block was alloc'd at
==4970==    at 0x483B7F3: malloc (in /usr/lib/x86_64-linux-gnu/valgrind/vgpreload_memcheck-amd64-linux.so)
==4970==    by 0x5B8F63: PyObject_Malloc (in /usr/bin/python3.8)
==4970==    by 0x5CDC05: ??? (in /usr/bin/python3.8)
==4970==    by 0x5CEEEF: PyDict_SetItem (in /usr/bin/python3.8)
==4970==    by 0x5BFE1F: PyObject_SetAttr (in /usr/bin/python3.8)
==4970==    by 0x5C235C: ??? (in /usr/bin/python3.8)
==4970==    by 0x6A55B1: PyModule_AddFunctions (in /usr/bin/python3.8)
==4970==    by 0x6A5829: _PyModule_CreateInitialized (in /usr/bin/python3.8)
==4970==    by 0x639ECD: PyInit_posix (in /usr/bin/python3.8)
==4970==    by 0x5524A9: ??? (in /usr/bin/python3.8)
==4970==    by 0x5C3A3F: ??? (in /usr/bin/python3.8)
==4970==    by 0x5F257C: PyVectorcall_Call (in /usr/bin/python3.8)
==4970== 
==4970== Invalid read of size 4
==4970==    at 0x5B8222: PyObject_Free (in /usr/bin/python3.8)
==4970==    by 0x5CDC77: ??? (in /usr/bin/python3.8)
==4970==    by 0x5CFD32: PyDict_SetDefault (in /usr/bin/python3.8)
==4970==    by 0x5D07FC: PyDict_SetItemString (in /usr/bin/python3.8)
==4970==    by 0x640A45: ??? (in /usr/bin/python3.8)
==4970==    by 0x63ACA7: PyInit_posix (in /usr/bin/python3.8)
==4970==    by 0x5524A9: ??? (in /usr/bin/python3.8)
==4970==    by 0x5C3A3F: ??? (in /usr/bin/python3.8)
==4970==    by 0x5F257C: PyVectorcall_Call (in /usr/bin/python3.8)
==4970==    by 0x56FCB5: _PyEval_EvalFrameDefault (in /usr/bin/python3.8)
==4970==    by 0x568229: _PyEval_EvalCodeWithName (in /usr/bin/python3.8)
==4970==    by 0x5F6032: _PyFunction_Vectorcall (in /usr/bin/python3.8)
==4970==  Address 0x4c54020 is 16 bytes before a block of size 36,896 alloc'd
==4970==    at 0x483B7F3: malloc (in /usr/lib/x86_64-linux-gnu/valgrind/vgpreload_memcheck-amd64-linux.so)
==4970==    by 0x5B8F63: PyObject_Malloc (in /usr/bin/python3.8)
==4970==    by 0x5CDC05: ??? (in /usr/bin/python3.8)
==4970==    by 0x5CFD32: PyDict_SetDefault (in /usr/bin/python3.8)
==4970==    by 0x5756F5: PyUnicode_InternInPlace (in /usr/bin/python3.8)
==4970==    by 0x54DC63: ??? (in /usr/bin/python3.8)
==4970==    by 0x54DE61: ??? (in /usr/bin/python3.8)
==4970==    by 0x54E328: ??? (in /usr/bin/python3.8)
==4970==    by 0x54DE61: ??? (in /usr/bin/python3.8)
==4970==    by 0x54E312: ??? (in /usr/bin/python3.8)
==4970==    by 0x6808F4: PyMarshal_ReadObjectFromString (in /usr/bin/python3.8)
==4970==    by 0x68310F: PyImport_ImportFrozenModuleObject (in /usr/bin/python3.8)
==4970== 
==4970== Invalid read of size 4
==4970==    at 0x5B8222: PyObject_Free (in /usr/bin/python3.8)
==4970==    by 0x5CDC77: ??? (in /usr/bin/python3.8)
==4970==    by 0x5D0B1E: PyDict_SetItemString (in /usr/bin/python3.8)
==4970==    by 0x640A45: ??? (in /usr/bin/python3.8)
==4970==    by 0x63ACE5: PyInit_posix (in /usr/bin/python3.8)
==4970==    by 0x5524A9: ??? (in /usr/bin/python3.8)
==4970==    by 0x5C3A3F: ??? (in /usr/bin/python3.8)
==4970==    by 0x5F257C: PyVectorcall_Call (in /usr/bin/python3.8)
==4970==    by 0x56FCB5: _PyEval_EvalFrameDefault (in /usr/bin/python3.8)
==4970==    by 0x568229: _PyEval_EvalCodeWithName (in /usr/bin/python3.8)
==4970==    by 0x5F6032: _PyFunction_Vectorcall (in /usr/bin/python3.8)
==4970==    by 0x569F5D: _PyEval_EvalFrameDefault (in /usr/bin/python3.8)
==4970==  Address 0x4c92020 is 832 bytes inside a block of size 1,112 free'd
==4970==    at 0x483CA3F: free (in /usr/lib/x86_64-linux-gnu/valgrind/vgpreload_memcheck-amd64-linux.so)
==4970==    by 0x5CDC77: ??? (in /usr/bin/python3.8)
==4970==    by 0x5D0B1E: PyDict_SetItemString (in /usr/bin/python3.8)
==4970==    by 0x640A45: ??? (in /usr/bin/python3.8)
==4970==    by 0x63ACE5: PyInit_posix (in /usr/bin/python3.8)
==4970==    by 0x5524A9: ??? (in /usr/bin/python3.8)
==4970==    by 0x5C3A3F: ??? (in /usr/bin/python3.8)
==4970==    by 0x5F257C: PyVectorcall_Call (in /usr/bin/python3.8)
==4970==    by 0x56FCB5: _PyEval_EvalFrameDefault (in /usr/bin/python3.8)
==4970==    by 0x568229: _PyEval_EvalCodeWithName (in /usr/bin/python3.8)
==4970==    by 0x5F6032: _PyFunction_Vectorcall (in /usr/bin/python3.8)
==4970==    by 0x569F5D: _PyEval_EvalFrameDefault (in /usr/bin/python3.8)
==4970==  Block was alloc'd at
==4970==    at 0x483B7F3: malloc (in /usr/lib/x86_64-linux-gnu/valgrind/vgpreload_memcheck-amd64-linux.so)
==4970==    by 0x5B8F63: PyObject_Malloc (in /usr/bin/python3.8)
==4970==    by 0x5CDC05: ??? (in /usr/bin/python3.8)
==4970==    by 0x5D0B1E: PyDict_SetItemString (in /usr/bin/python3.8)
==4970==    by 0x640A45: ??? (in /usr/bin/python3.8)
==4970==    by 0x63ACE5: PyInit_posix (in /usr/bin/python3.8)
==4970==    by 0x5524A9: ??? (in /usr/bin/python3.8)
==4970==    by 0x5C3A3F: ??? (in /usr/bin/python3.8)
==4970==    by 0x5F257C: PyVectorcall_Call (in /usr/bin/python3.8)
==4970==    by 0x56FCB5: _PyEval_EvalFrameDefault (in /usr/bin/python3.8)
==4970==    by 0x568229: _PyEval_EvalCodeWithName (in /usr/bin/python3.8)
==4970==    by 0x5F6032: _PyFunction_Vectorcall (in /usr/bin/python3.8)
==4970== 
==4970== Invalid read of size 4
==4970==    at 0x5B9C3A: PyMem_Realloc (in /usr/bin/python3.8)
==4970==    by 0x5EA784: PyList_Append (in /usr/bin/python3.8)
==4970==    by 0x54DFB2: ??? (in /usr/bin/python3.8)
==4970==    by 0x54DDAA: ??? (in /usr/bin/python3.8)
==4970==    by 0x54E312: ??? (in /usr/bin/python3.8)
==4970==    by 0x54DE61: ??? (in /usr/bin/python3.8)
==4970==    by 0x54E312: ??? (in /usr/bin/python3.8)
==4970==    by 0x6808F4: PyMarshal_ReadObjectFromString (in /usr/bin/python3.8)
==4970==    by 0x5C3A3F: ??? (in /usr/bin/python3.8)
==4970==    by 0x5F257C: PyVectorcall_Call (in /usr/bin/python3.8)
==4970==    by 0x56FCB5: _PyEval_EvalFrameDefault (in /usr/bin/python3.8)
==4970==    by 0x568229: _PyEval_EvalCodeWithName (in /usr/bin/python3.8)
==4970==  Address 0x4c9c020 is 10 bytes after a block of size 966 free'd
==4970==    at 0x483DFAF: realloc (in /usr/lib/x86_64-linux-gnu/valgrind/vgpreload_memcheck-amd64-linux.so)
==4970==    by 0x59029C: ??? (in /usr/bin/python3.8)
==4970==    by 0x4F09DA: ??? (in /usr/bin/python3.8)
==4970==    by 0x54E5F6: ??? (in /usr/bin/python3.8)
==4970==    by 0x54DE61: ??? (in /usr/bin/python3.8)
==4970==    by 0x54E312: ??? (in /usr/bin/python3.8)
==4970==    by 0x6808F4: PyMarshal_ReadObjectFromString (in /usr/bin/python3.8)
==4970==    by 0x5C3A3F: ??? (in /usr/bin/python3.8)
==4970==    by 0x5F257C: PyVectorcall_Call (in /usr/bin/python3.8)
==4970==    by 0x56FCB5: _PyEval_EvalFrameDefault (in /usr/bin/python3.8)
==4970==    by 0x568229: _PyEval_EvalCodeWithName (in /usr/bin/python3.8)
==4970==    by 0x5F6032: _PyFunction_Vectorcall (in /usr/bin/python3.8)
==4970==  Block was alloc'd at
==4970==    at 0x483B7F3: malloc (in /usr/lib/x86_64-linux-gnu/valgrind/vgpreload_memcheck-amd64-linux.so)
==4970==    by 0x58FABB: PyUnicode_New (in /usr/bin/python3.8)
==4970==    by 0x57A1D0: _PyUnicodeWriter_PrepareInternal (in /usr/bin/python3.8)
==4970==    by 0x57B1AC: ??? (in /usr/bin/python3.8)
==4970==    by 0x4F0CA3: ??? (in /usr/bin/python3.8)
==4970==    by 0x54E5F6: ??? (in /usr/bin/python3.8)
==4970==    by 0x54DE61: ??? (in /usr/bin/python3.8)
==4970==    by 0x54E312: ??? (in /usr/bin/python3.8)
==4970==    by 0x6808F4: PyMarshal_ReadObjectFromString (in /usr/bin/python3.8)
==4970==    by 0x5C3A3F: ??? (in /usr/bin/python3.8)
==4970==    by 0x5F257C: PyVectorcall_Call (in /usr/bin/python3.8)
==4970==    by 0x56FCB5: _PyEval_EvalFrameDefault (in /usr/bin/python3.8)
==4970== 
==4970== 
==4970== Process terminating with default action of signal 2 (SIGINT)
==4970==    at 0x498065A: __open_nocancel (open64_nocancel.c:45)
==4970==    by 0x48FD244: _IO_file_open (fileops.c:186)
==4970==    by 0x48FD459: _IO_file_fopen@@GLIBC_2.2.5 (fileops.c:281)
==4970==    by 0x48EFB0D: __fopen_internal (iofopen.c:75)
==4970==    by 0x48EFB0D: fopen@@GLIBC_2.2.5 (iofopen.c:86)
==4970==    by 0x493FE37: __tzfile_read (tzfile.c:162)
==4970==    by 0x493F1D4: tzset_internal (tzset.c:405)
==4970==    by 0x493FB4B: __tz_convert (tzset.c:577)
==4970==    by 0x67A93C: _PyTime_localtime (in /usr/bin/python3.8)
==4970==    by 0x61C1B3: ??? (in /usr/bin/python3.8)
==4970==    by 0x61C308: PyInit_time (in /usr/bin/python3.8)
==4970==    by 0x5524A9: ??? (in /usr/bin/python3.8)
==4970==    by 0x5C3A3F: ??? (in /usr/bin/python3.8)
==4970== 
==4970== HEAP SUMMARY:
==4970==     in use at exit: 264,382 bytes in 206 blocks
==4970==   total heap usage: 427 allocs, 221 frees, 454,083 bytes allocated
==4970== 
==4970== Searching for pointers to 206 not-freed blocks
==4970== Checked 1,607,632 bytes
==4970== 
==4970== 544 bytes in 1 blocks are possibly lost in loss record 38 of 165
==4970==    at 0x483B7F3: malloc (in /usr/lib/x86_64-linux-gnu/valgrind/vgpreload_memcheck-amd64-linux.so)
==4970==    by 0x53A797: _PyObject_GC_NewVar (in /usr/bin/python3.8)
==4970==    by 0x56907A: _PyEval_EvalCodeWithName (in /usr/bin/python3.8)
==4970==    by 0x5F6032: _PyFunction_Vectorcall (in /usr/bin/python3.8)
==4970==    by 0x569F5D: _PyEval_EvalFrameDefault (in /usr/bin/python3.8)
==4970==    by 0x5F5E55: _PyFunction_Vectorcall (in /usr/bin/python3.8)
==4970==    by 0x569F5D: _PyEval_EvalFrameDefault (in /usr/bin/python3.8)
==4970==    by 0x5F5E55: _PyFunction_Vectorcall (in /usr/bin/python3.8)
==4970==    by 0x5F3A10: ??? (in /usr/bin/python3.8)
==4970==    by 0x5F3E97: _PyObject_CallMethodIdObjArgs (in /usr/bin/python3.8)
==4970==    by 0x551492: PyImport_ImportModuleLevelObject (in /usr/bin/python3.8)
==4970==    by 0x56C1E2: _PyEval_EvalFrameDefault (in /usr/bin/python3.8)
==4970== 
==4970== 552 bytes in 1 blocks are possibly lost in loss record 40 of 165
==4970==    at 0x483B7F3: malloc (in /usr/lib/x86_64-linux-gnu/valgrind/vgpreload_memcheck-amd64-linux.so)
==4970==    by 0x53A797: _PyObject_GC_NewVar (in /usr/bin/python3.8)
==4970==    by 0x5F624A: _PyFunction_Vectorcall (in /usr/bin/python3.8)
==4970==    by 0x569F5D: _PyEval_EvalFrameDefault (in /usr/bin/python3.8)
==4970==    by 0x5F5E55: _PyFunction_Vectorcall (in /usr/bin/python3.8)
==4970==    by 0x56EF96: _PyEval_EvalFrameDefault (in /usr/bin/python3.8)
==4970==    by 0x5F5E55: _PyFunction_Vectorcall (in /usr/bin/python3.8)
==4970==    by 0x6B2429: ??? (in /usr/bin/python3.8)
==4970==    by 0x6B2673: PyObject_CallMethod (in /usr/bin/python3.8)
==4970==    by 0x67ED72: ??? (in /usr/bin/python3.8)
==4970==    by 0x5FBD78: ??? (in /usr/bin/python3.8)
==4970==    by 0x67FF8F: Py_InitializeFromConfig (in /usr/bin/python3.8)
==4970== 
==4970== LEAK SUMMARY:
==4970==    definitely lost: 0 bytes in 0 blocks
==4970==    indirectly lost: 0 bytes in 0 blocks
==4970==      possibly lost: 1,096 bytes in 2 blocks
==4970==    still reachable: 263,286 bytes in 204 blocks
==4970==         suppressed: 0 bytes in 0 blocks
==4970== Reachable blocks (those to which a pointer was found) are not shown.
==4970== To see them, rerun with: --leak-check=full --show-leak-kinds=all
==4970== 
==4970== ERROR SUMMARY: 54 errors from 34 contexts (suppressed: 0 from 0)
==4970== 
==4970== 1 errors in context 1 of 34:
==4970== Invalid read of size 4
==4970==    at 0x5B9C3A: PyMem_Realloc (in /usr/bin/python3.8)
==4970==    by 0x5EA784: PyList_Append (in /usr/bin/python3.8)
==4970==    by 0x54DFB2: ??? (in /usr/bin/python3.8)
==4970==    by 0x54DDAA: ??? (in /usr/bin/python3.8)
==4970==    by 0x54E312: ??? (in /usr/bin/python3.8)
==4970==    by 0x54DE61: ??? (in /usr/bin/python3.8)
==4970==    by 0x54E312: ??? (in /usr/bin/python3.8)
==4970==    by 0x6808F4: PyMarshal_ReadObjectFromString (in /usr/bin/python3.8)
==4970==    by 0x5C3A3F: ??? (in /usr/bin/python3.8)
==4970==    by 0x5F257C: PyVectorcall_Call (in /usr/bin/python3.8)
==4970==    by 0x56FCB5: _PyEval_EvalFrameDefault (in /usr/bin/python3.8)
==4970==    by 0x568229: _PyEval_EvalCodeWithName (in /usr/bin/python3.8)
==4970==  Address 0x4c9c020 is 10 bytes after a block of size 966 free'd
==4970==    at 0x483DFAF: realloc (in /usr/lib/x86_64-linux-gnu/valgrind/vgpreload_memcheck-amd64-linux.so)
==4970==    by 0x59029C: ??? (in /usr/bin/python3.8)
==4970==    by 0x4F09DA: ??? (in /usr/bin/python3.8)
==4970==    by 0x54E5F6: ??? (in /usr/bin/python3.8)
==4970==    by 0x54DE61: ??? (in /usr/bin/python3.8)
==4970==    by 0x54E312: ??? (in /usr/bin/python3.8)
==4970==    by 0x6808F4: PyMarshal_ReadObjectFromString (in /usr/bin/python3.8)
==4970==    by 0x5C3A3F: ??? (in /usr/bin/python3.8)
==4970==    by 0x5F257C: PyVectorcall_Call (in /usr/bin/python3.8)
==4970==    by 0x56FCB5: _PyEval_EvalFrameDefault (in /usr/bin/python3.8)
==4970==    by 0x568229: _PyEval_EvalCodeWithName (in /usr/bin/python3.8)
==4970==    by 0x5F6032: _PyFunction_Vectorcall (in /usr/bin/python3.8)
==4970==  Block was alloc'd at
==4970==    at 0x483B7F3: malloc (in /usr/lib/x86_64-linux-gnu/valgrind/vgpreload_memcheck-amd64-linux.so)
==4970==    by 0x58FABB: PyUnicode_New (in /usr/bin/python3.8)
==4970==    by 0x57A1D0: _PyUnicodeWriter_PrepareInternal (in /usr/bin/python3.8)
==4970==    by 0x57B1AC: ??? (in /usr/bin/python3.8)
==4970==    by 0x4F0CA3: ??? (in /usr/bin/python3.8)
==4970==    by 0x54E5F6: ??? (in /usr/bin/python3.8)
==4970==    by 0x54DE61: ??? (in /usr/bin/python3.8)
==4970==    by 0x54E312: ??? (in /usr/bin/python3.8)
==4970==    by 0x6808F4: PyMarshal_ReadObjectFromString (in /usr/bin/python3.8)
==4970==    by 0x5C3A3F: ??? (in /usr/bin/python3.8)
==4970==    by 0x5F257C: PyVectorcall_Call (in /usr/bin/python3.8)
==4970==    by 0x56FCB5: _PyEval_EvalFrameDefault (in /usr/bin/python3.8)
==4970== 
==4970== 
==4970== 1 errors in context 2 of 34:
==4970== Invalid read of size 4
==4970==    at 0x5B8222: PyObject_Free (in /usr/bin/python3.8)
==4970==    by 0x5CDC77: ??? (in /usr/bin/python3.8)
==4970==    by 0x5D0B1E: PyDict_SetItemString (in /usr/bin/python3.8)
==4970==    by 0x640A45: ??? (in /usr/bin/python3.8)
==4970==    by 0x63ACE5: PyInit_posix (in /usr/bin/python3.8)
==4970==    by 0x5524A9: ??? (in /usr/bin/python3.8)
==4970==    by 0x5C3A3F: ??? (in /usr/bin/python3.8)
==4970==    by 0x5F257C: PyVectorcall_Call (in /usr/bin/python3.8)
==4970==    by 0x56FCB5: _PyEval_EvalFrameDefault (in /usr/bin/python3.8)
==4970==    by 0x568229: _PyEval_EvalCodeWithName (in /usr/bin/python3.8)
==4970==    by 0x5F6032: _PyFunction_Vectorcall (in /usr/bin/python3.8)
==4970==    by 0x569F5D: _PyEval_EvalFrameDefault (in /usr/bin/python3.8)
==4970==  Address 0x4c92020 is 832 bytes inside a block of size 1,112 free'd
==4970==    at 0x483CA3F: free (in /usr/lib/x86_64-linux-gnu/valgrind/vgpreload_memcheck-amd64-linux.so)
==4970==    by 0x5CDC77: ??? (in /usr/bin/python3.8)
==4970==    by 0x5D0B1E: PyDict_SetItemString (in /usr/bin/python3.8)
==4970==    by 0x640A45: ??? (in /usr/bin/python3.8)
==4970==    by 0x63ACE5: PyInit_posix (in /usr/bin/python3.8)
==4970==    by 0x5524A9: ??? (in /usr/bin/python3.8)
==4970==    by 0x5C3A3F: ??? (in /usr/bin/python3.8)
==4970==    by 0x5F257C: PyVectorcall_Call (in /usr/bin/python3.8)
==4970==    by 0x56FCB5: _PyEval_EvalFrameDefault (in /usr/bin/python3.8)
==4970==    by 0x568229: _PyEval_EvalCodeWithName (in /usr/bin/python3.8)
==4970==    by 0x5F6032: _PyFunction_Vectorcall (in /usr/bin/python3.8)
==4970==    by 0x569F5D: _PyEval_EvalFrameDefault (in /usr/bin/python3.8)
==4970==  Block was alloc'd at
==4970==    at 0x483B7F3: malloc (in /usr/lib/x86_64-linux-gnu/valgrind/vgpreload_memcheck-amd64-linux.so)
==4970==    by 0x5B8F63: PyObject_Malloc (in /usr/bin/python3.8)
==4970==    by 0x5CDC05: ??? (in /usr/bin/python3.8)
==4970==    by 0x5D0B1E: PyDict_SetItemString (in /usr/bin/python3.8)
==4970==    by 0x640A45: ??? (in /usr/bin/python3.8)
==4970==    by 0x63ACE5: PyInit_posix (in /usr/bin/python3.8)
==4970==    by 0x5524A9: ??? (in /usr/bin/python3.8)
==4970==    by 0x5C3A3F: ??? (in /usr/bin/python3.8)
==4970==    by 0x5F257C: PyVectorcall_Call (in /usr/bin/python3.8)
==4970==    by 0x56FCB5: _PyEval_EvalFrameDefault (in /usr/bin/python3.8)
==4970==    by 0x568229: _PyEval_EvalCodeWithName (in /usr/bin/python3.8)
==4970==    by 0x5F6032: _PyFunction_Vectorcall (in /usr/bin/python3.8)
==4970== 
==4970== 
==4970== 1 errors in context 3 of 34:
==4970== Invalid read of size 4
==4970==    at 0x5B8222: PyObject_Free (in /usr/bin/python3.8)
==4970==    by 0x5CDC77: ??? (in /usr/bin/python3.8)
==4970==    by 0x5CFD32: PyDict_SetDefault (in /usr/bin/python3.8)
==4970==    by 0x5D07FC: PyDict_SetItemString (in /usr/bin/python3.8)
==4970==    by 0x640A45: ??? (in /usr/bin/python3.8)
==4970==    by 0x63ACA7: PyInit_posix (in /usr/bin/python3.8)
==4970==    by 0x5524A9: ??? (in /usr/bin/python3.8)
==4970==    by 0x5C3A3F: ??? (in /usr/bin/python3.8)
==4970==    by 0x5F257C: PyVectorcall_Call (in /usr/bin/python3.8)
==4970==    by 0x56FCB5: _PyEval_EvalFrameDefault (in /usr/bin/python3.8)
==4970==    by 0x568229: _PyEval_EvalCodeWithName (in /usr/bin/python3.8)
==4970==    by 0x5F6032: _PyFunction_Vectorcall (in /usr/bin/python3.8)
==4970==  Address 0x4c54020 is 16 bytes before a block of size 36,896 alloc'd
==4970==    at 0x483B7F3: malloc (in /usr/lib/x86_64-linux-gnu/valgrind/vgpreload_memcheck-amd64-linux.so)
==4970==    by 0x5B8F63: PyObject_Malloc (in /usr/bin/python3.8)
==4970==    by 0x5CDC05: ??? (in /usr/bin/python3.8)
==4970==    by 0x5CFD32: PyDict_SetDefault (in /usr/bin/python3.8)
==4970==    by 0x5756F5: PyUnicode_InternInPlace (in /usr/bin/python3.8)
==4970==    by 0x54DC63: ??? (in /usr/bin/python3.8)
==4970==    by 0x54DE61: ??? (in /usr/bin/python3.8)
==4970==    by 0x54E328: ??? (in /usr/bin/python3.8)
==4970==    by 0x54DE61: ??? (in /usr/bin/python3.8)
==4970==    by 0x54E312: ??? (in /usr/bin/python3.8)
==4970==    by 0x6808F4: PyMarshal_ReadObjectFromString (in /usr/bin/python3.8)
==4970==    by 0x68310F: PyImport_ImportFrozenModuleObject (in /usr/bin/python3.8)
==4970== 
==4970== 
==4970== 1 errors in context 4 of 34:
==4970== Invalid read of size 4
==4970==    at 0x5B8222: PyObject_Free (in /usr/bin/python3.8)
==4970==    by 0x5CDC77: ??? (in /usr/bin/python3.8)
==4970==    by 0x54A5F5: PyModule_AddIntConstant (in /usr/bin/python3.8)
==4970==    by 0x63A0C2: PyInit_posix (in /usr/bin/python3.8)
==4970==    by 0x5524A9: ??? (in /usr/bin/python3.8)
==4970==    by 0x5C3A3F: ??? (in /usr/bin/python3.8)
==4970==    by 0x5F257C: PyVectorcall_Call (in /usr/bin/python3.8)
==4970==    by 0x56FCB5: _PyEval_EvalFrameDefault (in /usr/bin/python3.8)
==4970==    by 0x568229: _PyEval_EvalCodeWithName (in /usr/bin/python3.8)
==4970==    by 0x5F6032: _PyFunction_Vectorcall (in /usr/bin/python3.8)
==4970==    by 0x569F5D: _PyEval_EvalFrameDefault (in /usr/bin/python3.8)
==4970==    by 0x50A23D: ??? (in /usr/bin/python3.8)
==4970==  Address 0x4c79020 is 736 bytes inside a block of size 1,112 free'd
==4970==    at 0x483CA3F: free (in /usr/lib/x86_64-linux-gnu/valgrind/vgpreload_memcheck-amd64-linux.so)
==4970==    by 0x5CDC77: ??? (in /usr/bin/python3.8)
==4970==    by 0x5CEEEF: PyDict_SetItem (in /usr/bin/python3.8)
==4970==    by 0x5BFE1F: PyObject_SetAttr (in /usr/bin/python3.8)
==4970==    by 0x5C235C: ??? (in /usr/bin/python3.8)
==4970==    by 0x6A55B1: PyModule_AddFunctions (in /usr/bin/python3.8)
==4970==    by 0x6A5829: _PyModule_CreateInitialized (in /usr/bin/python3.8)
==4970==    by 0x639ECD: PyInit_posix (in /usr/bin/python3.8)
==4970==    by 0x5524A9: ??? (in /usr/bin/python3.8)
==4970==    by 0x5C3A3F: ??? (in /usr/bin/python3.8)
==4970==    by 0x5F257C: PyVectorcall_Call (in /usr/bin/python3.8)
==4970==    by 0x56FCB5: _PyEval_EvalFrameDefault (in /usr/bin/python3.8)
==4970==  Block was alloc'd at
==4970==    at 0x483B7F3: malloc (in /usr/lib/x86_64-linux-gnu/valgrind/vgpreload_memcheck-amd64-linux.so)
==4970==    by 0x5B8F63: PyObject_Malloc (in /usr/bin/python3.8)
==4970==    by 0x5CDC05: ??? (in /usr/bin/python3.8)
==4970==    by 0x5CEEEF: PyDict_SetItem (in /usr/bin/python3.8)
==4970==    by 0x5BFE1F: PyObject_SetAttr (in /usr/bin/python3.8)
==4970==    by 0x5C235C: ??? (in /usr/bin/python3.8)
==4970==    by 0x6A55B1: PyModule_AddFunctions (in /usr/bin/python3.8)
==4970==    by 0x6A5829: _PyModule_CreateInitialized (in /usr/bin/python3.8)
==4970==    by 0x639ECD: PyInit_posix (in /usr/bin/python3.8)
==4970==    by 0x5524A9: ??? (in /usr/bin/python3.8)
==4970==    by 0x5C3A3F: ??? (in /usr/bin/python3.8)
==4970==    by 0x5F257C: PyVectorcall_Call (in /usr/bin/python3.8)
==4970== 
==4970== 
==4970== 1 errors in context 5 of 34:
==4970== Invalid read of size 4
==4970==    at 0x5B8222: PyObject_Free (in /usr/bin/python3.8)
==4970==    by 0x5CDC77: ??? (in /usr/bin/python3.8)
==4970==    by 0x5CEEEF: PyDict_SetItem (in /usr/bin/python3.8)
==4970==    by 0x5BFE1F: PyObject_SetAttr (in /usr/bin/python3.8)
==4970==    by 0x5C235C: ??? (in /usr/bin/python3.8)
==4970==    by 0x6A55B1: PyModule_AddFunctions (in /usr/bin/python3.8)
==4970==    by 0x6A5829: _PyModule_CreateInitialized (in /usr/bin/python3.8)
==4970==    by 0x639ECD: PyInit_posix (in /usr/bin/python3.8)
==4970==    by 0x5524A9: ??? (in /usr/bin/python3.8)
==4970==    by 0x5C3A3F: ??? (in /usr/bin/python3.8)
==4970==    by 0x5F257C: PyVectorcall_Call (in /usr/bin/python3.8)
==4970==    by 0x56FCB5: _PyEval_EvalFrameDefault (in /usr/bin/python3.8)
==4970==  Address 0x4c79020 is 736 bytes inside a block of size 1,112 free'd
==4970==    at 0x483CA3F: free (in /usr/lib/x86_64-linux-gnu/valgrind/vgpreload_memcheck-amd64-linux.so)
==4970==    by 0x5CDC77: ??? (in /usr/bin/python3.8)
==4970==    by 0x5CEEEF: PyDict_SetItem (in /usr/bin/python3.8)
==4970==    by 0x5BFE1F: PyObject_SetAttr (in /usr/bin/python3.8)
==4970==    by 0x5C235C: ??? (in /usr/bin/python3.8)
==4970==    by 0x6A55B1: PyModule_AddFunctions (in /usr/bin/python3.8)
==4970==    by 0x6A5829: _PyModule_CreateInitialized (in /usr/bin/python3.8)
==4970==    by 0x639ECD: PyInit_posix (in /usr/bin/python3.8)
==4970==    by 0x5524A9: ??? (in /usr/bin/python3.8)
==4970==    by 0x5C3A3F: ??? (in /usr/bin/python3.8)
==4970==    by 0x5F257C: PyVectorcall_Call (in /usr/bin/python3.8)
==4970==    by 0x56FCB5: _PyEval_EvalFrameDefault (in /usr/bin/python3.8)
==4970==  Block was alloc'd at
==4970==    at 0x483B7F3: malloc (in /usr/lib/x86_64-linux-gnu/valgrind/vgpreload_memcheck-amd64-linux.so)
==4970==    by 0x5B8F63: PyObject_Malloc (in /usr/bin/python3.8)
==4970==    by 0x5CDC05: ??? (in /usr/bin/python3.8)
==4970==    by 0x5CEEEF: PyDict_SetItem (in /usr/bin/python3.8)
==4970==    by 0x5BFE1F: PyObject_SetAttr (in /usr/bin/python3.8)
==4970==    by 0x5C235C: ??? (in /usr/bin/python3.8)
==4970==    by 0x6A55B1: PyModule_AddFunctions (in /usr/bin/python3.8)
==4970==    by 0x6A5829: _PyModule_CreateInitialized (in /usr/bin/python3.8)
==4970==    by 0x639ECD: PyInit_posix (in /usr/bin/python3.8)
==4970==    by 0x5524A9: ??? (in /usr/bin/python3.8)
==4970==    by 0x5C3A3F: ??? (in /usr/bin/python3.8)
==4970==    by 0x5F257C: PyVectorcall_Call (in /usr/bin/python3.8)
==4970== 
==4970== 
==4970== 1 errors in context 6 of 34:
==4970== Invalid read of size 4
==4970==    at 0x5B8222: PyObject_Free (in /usr/bin/python3.8)
==4970==    by 0x5ADAD8: ??? (in /usr/bin/python3.8)
==4970==    by 0x506081: ??? (in /usr/bin/python3.8)
==4970==    by 0x5EBBD7: ??? (in /usr/bin/python3.8)
==4970==    by 0x5F5E8C: _PyFunction_Vectorcall (in /usr/bin/python3.8)
==4970==    by 0x56EF96: _PyEval_EvalFrameDefault (in /usr/bin/python3.8)
==4970==    by 0x5F5E55: _PyFunction_Vectorcall (in /usr/bin/python3.8)
==4970==    by 0x569F5D: _PyEval_EvalFrameDefault (in /usr/bin/python3.8)
==4970==    by 0x5F5E55: _PyFunction_Vectorcall (in /usr/bin/python3.8)
==4970==    by 0x569F5D: _PyEval_EvalFrameDefault (in /usr/bin/python3.8)
==4970==    by 0x5F5E55: _PyFunction_Vectorcall (in /usr/bin/python3.8)
==4970==    by 0x5F3A10: ??? (in /usr/bin/python3.8)
==4970==  Address 0x4c6b020 is 416 bytes inside a block of size 2,832 free'd
==4970==    at 0x483CA3F: free (in /usr/lib/x86_64-linux-gnu/valgrind/vgpreload_memcheck-amd64-linux.so)
==4970==    by 0x5EB98C: ??? (in /usr/bin/python3.8)
==4970==    by 0x680907: PyMarshal_ReadObjectFromString (in /usr/bin/python3.8)
==4970==    by 0x5C3A3F: ??? (in /usr/bin/python3.8)
==4970==    by 0x5F257C: PyVectorcall_Call (in /usr/bin/python3.8)
==4970==    by 0x56FCB5: _PyEval_EvalFrameDefault (in /usr/bin/python3.8)
==4970==    by 0x568229: _PyEval_EvalCodeWithName (in /usr/bin/python3.8)
==4970==    by 0x5F6032: _PyFunction_Vectorcall (in /usr/bin/python3.8)
==4970==    by 0x569F5D: _PyEval_EvalFrameDefault (in /usr/bin/python3.8)
==4970==    by 0x5F5E55: _PyFunction_Vectorcall (in /usr/bin/python3.8)
==4970==    by 0x56EF96: _PyEval_EvalFrameDefault (in /usr/bin/python3.8)
==4970==    by 0x5F5E55: _PyFunction_Vectorcall (in /usr/bin/python3.8)
==4970==  Block was alloc'd at
==4970==    at 0x483DFAF: realloc (in /usr/lib/x86_64-linux-gnu/valgrind/vgpreload_memcheck-amd64-linux.so)
==4970==    by 0x5EA784: PyList_Append (in /usr/bin/python3.8)
==4970==    by 0x54DC88: ??? (in /usr/bin/python3.8)
==4970==    by 0x54E394: ??? (in /usr/bin/python3.8)
==4970==    by 0x54DDAA: ??? (in /usr/bin/python3.8)
==4970==    by 0x54E312: ??? (in /usr/bin/python3.8)
==4970==    by 0x54DE61: ??? (in /usr/bin/python3.8)
==4970==    by 0x54E312: ??? (in /usr/bin/python3.8)
==4970==    by 0x6808F4: PyMarshal_ReadObjectFromString (in /usr/bin/python3.8)
==4970==    by 0x5C3A3F: ??? (in /usr/bin/python3.8)
==4970==    by 0x5F257C: PyVectorcall_Call (in /usr/bin/python3.8)
==4970==    by 0x56FCB5: _PyEval_EvalFrameDefault (in /usr/bin/python3.8)
==4970== 
==4970== 
==4970== 1 errors in context 7 of 34:
==4970== Use of uninitialised value of size 8
==4970==    at 0x5B8244: PyObject_Free (in /usr/bin/python3.8)
==4970==    by 0x5ADAD8: ??? (in /usr/bin/python3.8)
==4970==    by 0x50606B: ??? (in /usr/bin/python3.8)
==4970==    by 0x5EBBD7: ??? (in /usr/bin/python3.8)
==4970==    by 0x5F5E8C: _PyFunction_Vectorcall (in /usr/bin/python3.8)
==4970==    by 0x56EF96: _PyEval_EvalFrameDefault (in /usr/bin/python3.8)
==4970==    by 0x5F5E55: _PyFunction_Vectorcall (in /usr/bin/python3.8)
==4970==    by 0x569F5D: _PyEval_EvalFrameDefault (in /usr/bin/python3.8)
==4970==    by 0x5F5E55: _PyFunction_Vectorcall (in /usr/bin/python3.8)
==4970==    by 0x569F5D: _PyEval_EvalFrameDefault (in /usr/bin/python3.8)
==4970==    by 0x5F5E55: _PyFunction_Vectorcall (in /usr/bin/python3.8)
==4970==    by 0x5F3A10: ??? (in /usr/bin/python3.8)
==4970==  Uninitialised value was created by a heap allocation
==4970==    at 0x483B7F3: malloc (in /usr/lib/x86_64-linux-gnu/valgrind/vgpreload_memcheck-amd64-linux.so)
==4970==    by 0x53A797: _PyObject_GC_NewVar (in /usr/bin/python3.8)
==4970==    by 0x56907A: _PyEval_EvalCodeWithName (in /usr/bin/python3.8)
==4970==    by 0x5F6032: _PyFunction_Vectorcall (in /usr/bin/python3.8)
==4970==    by 0x569F5D: _PyEval_EvalFrameDefault (in /usr/bin/python3.8)
==4970==    by 0x5F5E55: _PyFunction_Vectorcall (in /usr/bin/python3.8)
==4970==    by 0x569F5D: _PyEval_EvalFrameDefault (in /usr/bin/python3.8)
==4970==    by 0x5F5E55: _PyFunction_Vectorcall (in /usr/bin/python3.8)
==4970==    by 0x5F3A10: ??? (in /usr/bin/python3.8)
==4970==    by 0x5F3E97: _PyObject_CallMethodIdObjArgs (in /usr/bin/python3.8)
==4970==    by 0x551492: PyImport_ImportModuleLevelObject (in /usr/bin/python3.8)
==4970==    by 0x56C1E2: _PyEval_EvalFrameDefault (in /usr/bin/python3.8)
==4970== 
==4970== 
==4970== 1 errors in context 8 of 34:
==4970== Conditional jump or move depends on uninitialised value(s)
==4970==    at 0x5B822C: PyObject_Free (in /usr/bin/python3.8)
==4970==    by 0x5ADAD8: ??? (in /usr/bin/python3.8)
==4970==    by 0x50606B: ??? (in /usr/bin/python3.8)
==4970==    by 0x5EBBD7: ??? (in /usr/bin/python3.8)
==4970==    by 0x5F5E8C: _PyFunction_Vectorcall (in /usr/bin/python3.8)
==4970==    by 0x56EF96: _PyEval_EvalFrameDefault (in /usr/bin/python3.8)
==4970==    by 0x5F5E55: _PyFunction_Vectorcall (in /usr/bin/python3.8)
==4970==    by 0x569F5D: _PyEval_EvalFrameDefault (in /usr/bin/python3.8)
==4970==    by 0x5F5E55: _PyFunction_Vectorcall (in /usr/bin/python3.8)
==4970==    by 0x569F5D: _PyEval_EvalFrameDefault (in /usr/bin/python3.8)
==4970==    by 0x5F5E55: _PyFunction_Vectorcall (in /usr/bin/python3.8)
==4970==    by 0x5F3A10: ??? (in /usr/bin/python3.8)
==4970==  Uninitialised value was created by a heap allocation
==4970==    at 0x483B7F3: malloc (in /usr/lib/x86_64-linux-gnu/valgrind/vgpreload_memcheck-amd64-linux.so)
==4970==    by 0x53A797: _PyObject_GC_NewVar (in /usr/bin/python3.8)
==4970==    by 0x56907A: _PyEval_EvalCodeWithName (in /usr/bin/python3.8)
==4970==    by 0x5F6032: _PyFunction_Vectorcall (in /usr/bin/python3.8)
==4970==    by 0x569F5D: _PyEval_EvalFrameDefault (in /usr/bin/python3.8)
==4970==    by 0x5F5E55: _PyFunction_Vectorcall (in /usr/bin/python3.8)
==4970==    by 0x569F5D: _PyEval_EvalFrameDefault (in /usr/bin/python3.8)
==4970==    by 0x5F5E55: _PyFunction_Vectorcall (in /usr/bin/python3.8)
==4970==    by 0x5F3A10: ??? (in /usr/bin/python3.8)
==4970==    by 0x5F3E97: _PyObject_CallMethodIdObjArgs (in /usr/bin/python3.8)
==4970==    by 0x551492: PyImport_ImportModuleLevelObject (in /usr/bin/python3.8)
==4970==    by 0x56C1E2: _PyEval_EvalFrameDefault (in /usr/bin/python3.8)
==4970== 
==4970== 
==4970== 1 errors in context 9 of 34:
==4970== Use of uninitialised value of size 8
==4970==    at 0x59C1D4: ??? (in /usr/bin/python3.8)
==4970==    by 0x506055: ??? (in /usr/bin/python3.8)
==4970==    by 0x5EBBD7: ??? (in /usr/bin/python3.8)
==4970==    by 0x5F5E8C: _PyFunction_Vectorcall (in /usr/bin/python3.8)
==4970==    by 0x56EF96: _PyEval_EvalFrameDefault (in /usr/bin/python3.8)
==4970==    by 0x5F5E55: _PyFunction_Vectorcall (in /usr/bin/python3.8)
==4970==    by 0x569F5D: _PyEval_EvalFrameDefault (in /usr/bin/python3.8)
==4970==    by 0x5F5E55: _PyFunction_Vectorcall (in /usr/bin/python3.8)
==4970==    by 0x569F5D: _PyEval_EvalFrameDefault (in /usr/bin/python3.8)
==4970==    by 0x5F5E55: _PyFunction_Vectorcall (in /usr/bin/python3.8)
==4970==    by 0x5F3A10: ??? (in /usr/bin/python3.8)
==4970==    by 0x5F3E97: _PyObject_CallMethodIdObjArgs (in /usr/bin/python3.8)
==4970==  Uninitialised value was created by a heap allocation
==4970==    at 0x483B7F3: malloc (in /usr/lib/x86_64-linux-gnu/valgrind/vgpreload_memcheck-amd64-linux.so)
==4970==    by 0x53A797: _PyObject_GC_NewVar (in /usr/bin/python3.8)
==4970==    by 0x56907A: _PyEval_EvalCodeWithName (in /usr/bin/python3.8)
==4970==    by 0x5F6032: _PyFunction_Vectorcall (in /usr/bin/python3.8)
==4970==    by 0x569F5D: _PyEval_EvalFrameDefault (in /usr/bin/python3.8)
==4970==    by 0x5F5E55: _PyFunction_Vectorcall (in /usr/bin/python3.8)
==4970==    by 0x569F5D: _PyEval_EvalFrameDefault (in /usr/bin/python3.8)
==4970==    by 0x5F5E55: _PyFunction_Vectorcall (in /usr/bin/python3.8)
==4970==    by 0x5F3A10: ??? (in /usr/bin/python3.8)
==4970==    by 0x5F3E97: _PyObject_CallMethodIdObjArgs (in /usr/bin/python3.8)
==4970==    by 0x551492: PyImport_ImportModuleLevelObject (in /usr/bin/python3.8)
==4970==    by 0x56C1E2: _PyEval_EvalFrameDefault (in /usr/bin/python3.8)
==4970== 
==4970== 
==4970== 1 errors in context 10 of 34:
==4970== Conditional jump or move depends on uninitialised value(s)
==4970==    at 0x59C1BC: ??? (in /usr/bin/python3.8)
==4970==    by 0x506055: ??? (in /usr/bin/python3.8)
==4970==    by 0x5EBBD7: ??? (in /usr/bin/python3.8)
==4970==    by 0x5F5E8C: _PyFunction_Vectorcall (in /usr/bin/python3.8)
==4970==    by 0x56EF96: _PyEval_EvalFrameDefault (in /usr/bin/python3.8)
==4970==    by 0x5F5E55: _PyFunction_Vectorcall (in /usr/bin/python3.8)
==4970==    by 0x569F5D: _PyEval_EvalFrameDefault (in /usr/bin/python3.8)
==4970==    by 0x5F5E55: _PyFunction_Vectorcall (in /usr/bin/python3.8)
==4970==    by 0x569F5D: _PyEval_EvalFrameDefault (in /usr/bin/python3.8)
==4970==    by 0x5F5E55: _PyFunction_Vectorcall (in /usr/bin/python3.8)
==4970==    by 0x5F3A10: ??? (in /usr/bin/python3.8)
==4970==    by 0x5F3E97: _PyObject_CallMethodIdObjArgs (in /usr/bin/python3.8)
==4970==  Uninitialised value was created by a heap allocation
==4970==    at 0x483B7F3: malloc (in /usr/lib/x86_64-linux-gnu/valgrind/vgpreload_memcheck-amd64-linux.so)
==4970==    by 0x53A797: _PyObject_GC_NewVar (in /usr/bin/python3.8)
==4970==    by 0x56907A: _PyEval_EvalCodeWithName (in /usr/bin/python3.8)
==4970==    by 0x5F6032: _PyFunction_Vectorcall (in /usr/bin/python3.8)
==4970==    by 0x569F5D: _PyEval_EvalFrameDefault (in /usr/bin/python3.8)
==4970==    by 0x5F5E55: _PyFunction_Vectorcall (in /usr/bin/python3.8)
==4970==    by 0x569F5D: _PyEval_EvalFrameDefault (in /usr/bin/python3.8)
==4970==    by 0x5F5E55: _PyFunction_Vectorcall (in /usr/bin/python3.8)
==4970==    by 0x5F3A10: ??? (in /usr/bin/python3.8)
==4970==    by 0x5F3E97: _PyObject_CallMethodIdObjArgs (in /usr/bin/python3.8)
==4970==    by 0x551492: PyImport_ImportModuleLevelObject (in /usr/bin/python3.8)
==4970==    by 0x56C1E2: _PyEval_EvalFrameDefault (in /usr/bin/python3.8)
==4970== 
==4970== 
==4970== 1 errors in context 11 of 34:
==4970== Invalid read of size 4
==4970==    at 0x5B8222: PyObject_Free (in /usr/bin/python3.8)
==4970==    by 0x5D1AEB: ??? (in /usr/bin/python3.8)
==4970==    by 0x5A785F: ??? (in /usr/bin/python3.8)
==4970==    by 0x5F3332: _PyObject_MakeTpCall (in /usr/bin/python3.8)
==4970==    by 0x4F735F: ??? (in /usr/bin/python3.8)
==4970==    by 0x5C3B96: ??? (in /usr/bin/python3.8)
==4970==    by 0x569F5D: _PyEval_EvalFrameDefault (in /usr/bin/python3.8)
==4970==    by 0x568229: _PyEval_EvalCodeWithName (in /usr/bin/python3.8)
==4970==    by 0x68C1E6: PyEval_EvalCode (in /usr/bin/python3.8)
==4970==    by 0x5FF1F3: ??? (in /usr/bin/python3.8)
==4970==    by 0x5C3CAF: ??? (in /usr/bin/python3.8)
==4970==    by 0x569F5D: _PyEval_EvalFrameDefault (in /usr/bin/python3.8)
==4970==  Address 0x4c6f020 is 16 bytes after a block of size 944 in arena "client"
==4970== 
==4970== 
==4970== 1 errors in context 12 of 34:
==4970== Invalid read of size 4
==4970==    at 0x5B9C3A: PyMem_Realloc (in /usr/bin/python3.8)
==4970==    by 0x5EA784: PyList_Append (in /usr/bin/python3.8)
==4970==    by 0x54DC88: ??? (in /usr/bin/python3.8)
==4970==    by 0x54DD0E: ??? (in /usr/bin/python3.8)
==4970==    by 0x54DD35: ??? (in /usr/bin/python3.8)
==4970==    by 0x54E312: ??? (in /usr/bin/python3.8)
==4970==    by 0x54DDAA: ??? (in /usr/bin/python3.8)
==4970==    by 0x54E312: ??? (in /usr/bin/python3.8)
==4970==    by 0x54DE61: ??? (in /usr/bin/python3.8)
==4970==    by 0x54E312: ??? (in /usr/bin/python3.8)
==4970==    by 0x6808F4: PyMarshal_ReadObjectFromString (in /usr/bin/python3.8)
==4970==    by 0x5C3A3F: ??? (in /usr/bin/python3.8)
==4970==  Address 0x4c69020 is 1,264 bytes inside a block of size 1,608 free'd
==4970==    at 0x483DFAF: realloc (in /usr/lib/x86_64-linux-gnu/valgrind/vgpreload_memcheck-amd64-linux.so)
==4970==    by 0x5EA784: PyList_Append (in /usr/bin/python3.8)
==4970==    by 0x54DC88: ??? (in /usr/bin/python3.8)
==4970==    by 0x54E394: ??? (in /usr/bin/python3.8)
==4970==    by 0x54DE1B: ??? (in /usr/bin/python3.8)
==4970==    by 0x54E312: ??? (in /usr/bin/python3.8)
==4970==    by 0x54DE61: ??? (in /usr/bin/python3.8)
==4970==    by 0x54E312: ??? (in /usr/bin/python3.8)
==4970==    by 0x6808F4: PyMarshal_ReadObjectFromString (in /usr/bin/python3.8)
==4970==    by 0x5C3A3F: ??? (in /usr/bin/python3.8)
==4970==    by 0x5F257C: PyVectorcall_Call (in /usr/bin/python3.8)
==4970==    by 0x56FCB5: _PyEval_EvalFrameDefault (in /usr/bin/python3.8)
==4970==  Block was alloc'd at
==4970==    at 0x483DFAF: realloc (in /usr/lib/x86_64-linux-gnu/valgrind/vgpreload_memcheck-amd64-linux.so)
==4970==    by 0x5EA784: PyList_Append (in /usr/bin/python3.8)
==4970==    by 0x54DC88: ??? (in /usr/bin/python3.8)
==4970==    by 0x54DD0E: ??? (in /usr/bin/python3.8)
==4970==    by 0x54E328: ??? (in /usr/bin/python3.8)
==4970==    by 0x54DE61: ??? (in /usr/bin/python3.8)
==4970==    by 0x54E312: ??? (in /usr/bin/python3.8)
==4970==    by 0x6808F4: PyMarshal_ReadObjectFromString (in /usr/bin/python3.8)
==4970==    by 0x5C3A3F: ??? (in /usr/bin/python3.8)
==4970==    by 0x5F257C: PyVectorcall_Call (in /usr/bin/python3.8)
==4970==    by 0x56FCB5: _PyEval_EvalFrameDefault (in /usr/bin/python3.8)
==4970==    by 0x568229: _PyEval_EvalCodeWithName (in /usr/bin/python3.8)
==4970== 
==4970== 
==4970== 1 errors in context 13 of 34:
==4970== Invalid read of size 4
==4970==    at 0x5B9C3A: PyMem_Realloc (in /usr/bin/python3.8)
==4970==    by 0x5EA784: PyList_Append (in /usr/bin/python3.8)
==4970==    by 0x54DFB2: ??? (in /usr/bin/python3.8)
==4970==    by 0x54DE61: ??? (in /usr/bin/python3.8)
==4970==    by 0x54E312: ??? (in /usr/bin/python3.8)
==4970==    by 0x54DE61: ??? (in /usr/bin/python3.8)
==4970==    by 0x54E312: ??? (in /usr/bin/python3.8)
==4970==    by 0x6808F4: PyMarshal_ReadObjectFromString (in /usr/bin/python3.8)
==4970==    by 0x5C3A3F: ??? (in /usr/bin/python3.8)
==4970==    by 0x5F257C: PyVectorcall_Call (in /usr/bin/python3.8)
==4970==    by 0x56FCB5: _PyEval_EvalFrameDefault (in /usr/bin/python3.8)
==4970==    by 0x568229: _PyEval_EvalCodeWithName (in /usr/bin/python3.8)
==4970==  Address 0x4c67020 is 512 bytes inside a block of size 704 free'd
==4970==    at 0x483DFAF: realloc (in /usr/lib/x86_64-linux-gnu/valgrind/vgpreload_memcheck-amd64-linux.so)
==4970==    by 0x5EA784: PyList_Append (in /usr/bin/python3.8)
==4970==    by 0x54DC88: ??? (in /usr/bin/python3.8)
==4970==    by 0x54DE61: ??? (in /usr/bin/python3.8)
==4970==    by 0x54E328: ??? (in /usr/bin/python3.8)
==4970==    by 0x54DE61: ??? (in /usr/bin/python3.8)
==4970==    by 0x54E312: ??? (in /usr/bin/python3.8)
==4970==    by 0x6808F4: PyMarshal_ReadObjectFromString (in /usr/bin/python3.8)
==4970==    by 0x5C3A3F: ??? (in /usr/bin/python3.8)
==4970==    by 0x5F257C: PyVectorcall_Call (in /usr/bin/python3.8)
==4970==    by 0x56FCB5: _PyEval_EvalFrameDefault (in /usr/bin/python3.8)
==4970==    by 0x568229: _PyEval_EvalCodeWithName (in /usr/bin/python3.8)
==4970==  Block was alloc'd at
==4970==    at 0x483DFAF: realloc (in /usr/lib/x86_64-linux-gnu/valgrind/vgpreload_memcheck-amd64-linux.so)
==4970==    by 0x5EA784: PyList_Append (in /usr/bin/python3.8)
==4970==    by 0x54DFB2: ??? (in /usr/bin/python3.8)
==4970==    by 0x54DE1B: ??? (in /usr/bin/python3.8)
==4970==    by 0x54E312: ??? (in /usr/bin/python3.8)
==4970==    by 0x54DE61: ??? (in /usr/bin/python3.8)
==4970==    by 0x54E312: ??? (in /usr/bin/python3.8)
==4970==    by 0x6808F4: PyMarshal_ReadObjectFromString (in /usr/bin/python3.8)
==4970==    by 0x5C3A3F: ??? (in /usr/bin/python3.8)
==4970==    by 0x5F257C: PyVectorcall_Call (in /usr/bin/python3.8)
==4970==    by 0x56FCB5: _PyEval_EvalFrameDefault (in /usr/bin/python3.8)
==4970==    by 0x568229: _PyEval_EvalCodeWithName (in /usr/bin/python3.8)
==4970== 
==4970== 
==4970== 1 errors in context 14 of 34:
==4970== Use of uninitialised value of size 8
==4970==    at 0x5B9C5B: PyMem_Realloc (in /usr/bin/python3.8)
==4970==    by 0x5EA784: PyList_Append (in /usr/bin/python3.8)
==4970==    by 0x54DC88: ??? (in /usr/bin/python3.8)
==4970==    by 0x54DE61: ??? (in /usr/bin/python3.8)
==4970==    by 0x54E328: ??? (in /usr/bin/python3.8)
==4970==    by 0x54DE61: ??? (in /usr/bin/python3.8)
==4970==    by 0x54E312: ??? (in /usr/bin/python3.8)
==4970==    by 0x6808F4: PyMarshal_ReadObjectFromString (in /usr/bin/python3.8)
==4970==    by 0x5C3A3F: ??? (in /usr/bin/python3.8)
==4970==    by 0x5F257C: PyVectorcall_Call (in /usr/bin/python3.8)
==4970==    by 0x56FCB5: _PyEval_EvalFrameDefault (in /usr/bin/python3.8)
==4970==    by 0x568229: _PyEval_EvalCodeWithName (in /usr/bin/python3.8)
==4970==  Uninitialised value was created by a heap allocation
==4970==    at 0x483B7F3: malloc (in /usr/lib/x86_64-linux-gnu/valgrind/vgpreload_memcheck-amd64-linux.so)
==4970==    by 0x53A797: _PyObject_GC_NewVar (in /usr/bin/python3.8)
==4970==    by 0x56907A: _PyEval_EvalCodeWithName (in /usr/bin/python3.8)
==4970==    by 0x5F6032: _PyFunction_Vectorcall (in /usr/bin/python3.8)
==4970==    by 0x569F5D: _PyEval_EvalFrameDefault (in /usr/bin/python3.8)
==4970==    by 0x5F5E55: _PyFunction_Vectorcall (in /usr/bin/python3.8)
==4970==    by 0x569F5D: _PyEval_EvalFrameDefault (in /usr/bin/python3.8)
==4970==    by 0x5F5E55: _PyFunction_Vectorcall (in /usr/bin/python3.8)
==4970==    by 0x5F3A10: ??? (in /usr/bin/python3.8)
==4970==    by 0x5F3E97: _PyObject_CallMethodIdObjArgs (in /usr/bin/python3.8)
==4970==    by 0x551492: PyImport_ImportModuleLevelObject (in /usr/bin/python3.8)
==4970==    by 0x56C1E2: _PyEval_EvalFrameDefault (in /usr/bin/python3.8)
==4970== 
==4970== 
==4970== 1 errors in context 15 of 34:
==4970== Conditional jump or move depends on uninitialised value(s)
==4970==    at 0x5B9C43: PyMem_Realloc (in /usr/bin/python3.8)
==4970==    by 0x5EA784: PyList_Append (in /usr/bin/python3.8)
==4970==    by 0x54DC88: ??? (in /usr/bin/python3.8)
==4970==    by 0x54DE61: ??? (in /usr/bin/python3.8)
==4970==    by 0x54E328: ??? (in /usr/bin/python3.8)
==4970==    by 0x54DE61: ??? (in /usr/bin/python3.8)
==4970==    by 0x54E312: ??? (in /usr/bin/python3.8)
==4970==    by 0x6808F4: PyMarshal_ReadObjectFromString (in /usr/bin/python3.8)
==4970==    by 0x5C3A3F: ??? (in /usr/bin/python3.8)
==4970==    by 0x5F257C: PyVectorcall_Call (in /usr/bin/python3.8)
==4970==    by 0x56FCB5: _PyEval_EvalFrameDefault (in /usr/bin/python3.8)
==4970==    by 0x568229: _PyEval_EvalCodeWithName (in /usr/bin/python3.8)
==4970==  Uninitialised value was created by a heap allocation
==4970==    at 0x483B7F3: malloc (in /usr/lib/x86_64-linux-gnu/valgrind/vgpreload_memcheck-amd64-linux.so)
==4970==    by 0x53A797: _PyObject_GC_NewVar (in /usr/bin/python3.8)
==4970==    by 0x56907A: _PyEval_EvalCodeWithName (in /usr/bin/python3.8)
==4970==    by 0x5F6032: _PyFunction_Vectorcall (in /usr/bin/python3.8)
==4970==    by 0x569F5D: _PyEval_EvalFrameDefault (in /usr/bin/python3.8)
==4970==    by 0x5F5E55: _PyFunction_Vectorcall (in /usr/bin/python3.8)
==4970==    by 0x569F5D: _PyEval_EvalFrameDefault (in /usr/bin/python3.8)
==4970==    by 0x5F5E55: _PyFunction_Vectorcall (in /usr/bin/python3.8)
==4970==    by 0x5F3A10: ??? (in /usr/bin/python3.8)
==4970==    by 0x5F3E97: _PyObject_CallMethodIdObjArgs (in /usr/bin/python3.8)
==4970==    by 0x551492: PyImport_ImportModuleLevelObject (in /usr/bin/python3.8)
==4970==    by 0x56C1E2: _PyEval_EvalFrameDefault (in /usr/bin/python3.8)
==4970== 
==4970== 
==4970== 1 errors in context 16 of 34:
==4970== Use of uninitialised value of size 8
==4970==    at 0x5B9C5B: PyMem_Realloc (in /usr/bin/python3.8)
==4970==    by 0x5EA784: PyList_Append (in /usr/bin/python3.8)
==4970==    by 0x54DFB2: ??? (in /usr/bin/python3.8)
==4970==    by 0x54DE1B: ??? (in /usr/bin/python3.8)
==4970==    by 0x54E312: ??? (in /usr/bin/python3.8)
==4970==    by 0x54DE61: ??? (in /usr/bin/python3.8)
==4970==    by 0x54E312: ??? (in /usr/bin/python3.8)
==4970==    by 0x6808F4: PyMarshal_ReadObjectFromString (in /usr/bin/python3.8)
==4970==    by 0x5C3A3F: ??? (in /usr/bin/python3.8)
==4970==    by 0x5F257C: PyVectorcall_Call (in /usr/bin/python3.8)
==4970==    by 0x56FCB5: _PyEval_EvalFrameDefault (in /usr/bin/python3.8)
==4970==    by 0x568229: _PyEval_EvalCodeWithName (in /usr/bin/python3.8)
==4970==  Uninitialised value was created by a heap allocation
==4970==    at 0x483B7F3: malloc (in /usr/lib/x86_64-linux-gnu/valgrind/vgpreload_memcheck-amd64-linux.so)
==4970==    by 0x53A797: _PyObject_GC_NewVar (in /usr/bin/python3.8)
==4970==    by 0x56907A: _PyEval_EvalCodeWithName (in /usr/bin/python3.8)
==4970==    by 0x5F6032: _PyFunction_Vectorcall (in /usr/bin/python3.8)
==4970==    by 0x569F5D: _PyEval_EvalFrameDefault (in /usr/bin/python3.8)
==4970==    by 0x5F5E55: _PyFunction_Vectorcall (in /usr/bin/python3.8)
==4970==    by 0x569F5D: _PyEval_EvalFrameDefault (in /usr/bin/python3.8)
==4970==    by 0x5F5E55: _PyFunction_Vectorcall (in /usr/bin/python3.8)
==4970==    by 0x5F3A10: ??? (in /usr/bin/python3.8)
==4970==    by 0x5F3E97: _PyObject_CallMethodIdObjArgs (in /usr/bin/python3.8)
==4970==    by 0x551492: PyImport_ImportModuleLevelObject (in /usr/bin/python3.8)
==4970==    by 0x56C1E2: _PyEval_EvalFrameDefault (in /usr/bin/python3.8)
==4970== 
==4970== 
==4970== 1 errors in context 17 of 34:
==4970== Conditional jump or move depends on uninitialised value(s)
==4970==    at 0x5B9C43: PyMem_Realloc (in /usr/bin/python3.8)
==4970==    by 0x5EA784: PyList_Append (in /usr/bin/python3.8)
==4970==    by 0x54DFB2: ??? (in /usr/bin/python3.8)
==4970==    by 0x54DE1B: ??? (in /usr/bin/python3.8)
==4970==    by 0x54E312: ??? (in /usr/bin/python3.8)
==4970==    by 0x54DE61: ??? (in /usr/bin/python3.8)
==4970==    by 0x54E312: ??? (in /usr/bin/python3.8)
==4970==    by 0x6808F4: PyMarshal_ReadObjectFromString (in /usr/bin/python3.8)
==4970==    by 0x5C3A3F: ??? (in /usr/bin/python3.8)
==4970==    by 0x5F257C: PyVectorcall_Call (in /usr/bin/python3.8)
==4970==    by 0x56FCB5: _PyEval_EvalFrameDefault (in /usr/bin/python3.8)
==4970==    by 0x568229: _PyEval_EvalCodeWithName (in /usr/bin/python3.8)
==4970==  Uninitialised value was created by a heap allocation
==4970==    at 0x483B7F3: malloc (in /usr/lib/x86_64-linux-gnu/valgrind/vgpreload_memcheck-amd64-linux.so)
==4970==    by 0x53A797: _PyObject_GC_NewVar (in /usr/bin/python3.8)
==4970==    by 0x56907A: _PyEval_EvalCodeWithName (in /usr/bin/python3.8)
==4970==    by 0x5F6032: _PyFunction_Vectorcall (in /usr/bin/python3.8)
==4970==    by 0x569F5D: _PyEval_EvalFrameDefault (in /usr/bin/python3.8)
==4970==    by 0x5F5E55: _PyFunction_Vectorcall (in /usr/bin/python3.8)
==4970==    by 0x569F5D: _PyEval_EvalFrameDefault (in /usr/bin/python3.8)
==4970==    by 0x5F5E55: _PyFunction_Vectorcall (in /usr/bin/python3.8)
==4970==    by 0x5F3A10: ??? (in /usr/bin/python3.8)
==4970==    by 0x5F3E97: _PyObject_CallMethodIdObjArgs (in /usr/bin/python3.8)
==4970==    by 0x551492: PyImport_ImportModuleLevelObject (in /usr/bin/python3.8)
==4970==    by 0x56C1E2: _PyEval_EvalFrameDefault (in /usr/bin/python3.8)
==4970== 
==4970== 
==4970== 1 errors in context 18 of 34:
==4970== Invalid read of size 4
==4970==    at 0x5B8222: PyObject_Free (in /usr/bin/python3.8)
==4970==    by 0x5ADAD8: ??? (in /usr/bin/python3.8)
==4970==    by 0x50606B: ??? (in /usr/bin/python3.8)
==4970==    by 0x683167: PyImport_ImportFrozenModuleObject (in /usr/bin/python3.8)
==4970==    by 0x6831B1: PyImport_ImportFrozenModule (in /usr/bin/python3.8)
==4970==    by 0x67EDC0: ??? (in /usr/bin/python3.8)
==4970==    by 0x67FF0B: Py_InitializeFromConfig (in /usr/bin/python3.8)
==4970==    by 0x6B63F5: ??? (in /usr/bin/python3.8)
==4970==    by 0x6B6450: ??? (in /usr/bin/python3.8)
==4970==    by 0x6B64BC: Py_BytesMain (in /usr/bin/python3.8)
==4970==    by 0x48910B2: (below main) (libc-start.c:308)
==4970==  Address 0x4c52020 is 16 bytes before a block of size 76 alloc'd
==4970==    at 0x483B7F3: malloc (in /usr/lib/x86_64-linux-gnu/valgrind/vgpreload_memcheck-amd64-linux.so)
==4970==    by 0x6A39EA: _PyMem_RawWcsdup (in /usr/bin/python3.8)
==4970==    by 0x67F9F1: ??? (in /usr/bin/python3.8)
==4970==    by 0x67FBA5: _PyConfig_WritePathConfig (in /usr/bin/python3.8)
==4970==    by 0x67FEDF: Py_InitializeFromConfig (in /usr/bin/python3.8)
==4970==    by 0x6B63F5: ??? (in /usr/bin/python3.8)
==4970==    by 0x6B6450: ??? (in /usr/bin/python3.8)
==4970==    by 0x6B64BC: Py_BytesMain (in /usr/bin/python3.8)
==4970==    by 0x48910B2: (below main) (libc-start.c:308)
==4970== 
==4970== 
==4970== 1 errors in context 19 of 34:
==4970== Invalid read of size 4
==4970==    at 0x5B9C3A: PyMem_Realloc (in /usr/bin/python3.8)
==4970==    by 0x5EA784: PyList_Append (in /usr/bin/python3.8)
==4970==    by 0x54DC88: ??? (in /usr/bin/python3.8)
==4970==    by 0x54DDD1: ??? (in /usr/bin/python3.8)
==4970==    by 0x54E328: ??? (in /usr/bin/python3.8)
==4970==    by 0x54DE61: ??? (in /usr/bin/python3.8)
==4970==    by 0x54E312: ??? (in /usr/bin/python3.8)
==4970==    by 0x6808F4: PyMarshal_ReadObjectFromString (in /usr/bin/python3.8)
==4970==    by 0x68310F: PyImport_ImportFrozenModuleObject (in /usr/bin/python3.8)
==4970==    by 0x6831B1: PyImport_ImportFrozenModule (in /usr/bin/python3.8)
==4970==    by 0x67EDC0: ??? (in /usr/bin/python3.8)
==4970==    by 0x67FF0B: Py_InitializeFromConfig (in /usr/bin/python3.8)
==4970==  Address 0x4c52020 is 16 bytes before a block of size 76 alloc'd
==4970==    at 0x483B7F3: malloc (in /usr/lib/x86_64-linux-gnu/valgrind/vgpreload_memcheck-amd64-linux.so)
==4970==    by 0x6A39EA: _PyMem_RawWcsdup (in /usr/bin/python3.8)
==4970==    by 0x67F9F1: ??? (in /usr/bin/python3.8)
==4970==    by 0x67FBA5: _PyConfig_WritePathConfig (in /usr/bin/python3.8)
==4970==    by 0x67FEDF: Py_InitializeFromConfig (in /usr/bin/python3.8)
==4970==    by 0x6B63F5: ??? (in /usr/bin/python3.8)
==4970==    by 0x6B6450: ??? (in /usr/bin/python3.8)
==4970==    by 0x6B64BC: Py_BytesMain (in /usr/bin/python3.8)
==4970==    by 0x48910B2: (below main) (libc-start.c:308)
==4970== 
==4970== 
==4970== 1 errors in context 20 of 34:
==4970== Invalid read of size 4
==4970==    at 0x5B8222: PyObject_Free (in /usr/bin/python3.8)
==4970==    by 0x5CDC77: ??? (in /usr/bin/python3.8)
==4970==    by 0x5D0B1E: PyDict_SetItemString (in /usr/bin/python3.8)
==4970==    by 0x6AF96A: _PyBuiltins_AddExceptions (in /usr/bin/python3.8)
==4970==    by 0x67FE63: Py_InitializeFromConfig (in /usr/bin/python3.8)
==4970==    by 0x6B63F5: ??? (in /usr/bin/python3.8)
==4970==    by 0x6B6450: ??? (in /usr/bin/python3.8)
==4970==    by 0x6B64BC: Py_BytesMain (in /usr/bin/python3.8)
==4970==    by 0x48910B2: (below main) (libc-start.c:308)
==4970==  Address 0x4c4e020 is 192 bytes inside a block of size 1,112 free'd
==4970==    at 0x483CA3F: free (in /usr/lib/x86_64-linux-gnu/valgrind/vgpreload_memcheck-amd64-linux.so)
==4970==    by 0x5CDC77: ??? (in /usr/bin/python3.8)
==4970==    by 0x5CEEEF: PyDict_SetItem (in /usr/bin/python3.8)
==4970==    by 0x5BFE1F: PyObject_SetAttr (in /usr/bin/python3.8)
==4970==    by 0x5C235C: ??? (in /usr/bin/python3.8)
==4970==    by 0x6A55B1: PyModule_AddFunctions (in /usr/bin/python3.8)
==4970==    by 0x6A5829: _PyModule_CreateInitialized (in /usr/bin/python3.8)
==4970==    by 0x5FE218: _PyBuiltin_Init (in /usr/bin/python3.8)
==4970==    by 0x67FE1D: Py_InitializeFromConfig (in /usr/bin/python3.8)
==4970==    by 0x6B63F5: ??? (in /usr/bin/python3.8)
==4970==    by 0x6B6450: ??? (in /usr/bin/python3.8)
==4970==    by 0x6B64BC: Py_BytesMain (in /usr/bin/python3.8)
==4970==  Block was alloc'd at
==4970==    at 0x483B7F3: malloc (in /usr/lib/x86_64-linux-gnu/valgrind/vgpreload_memcheck-amd64-linux.so)
==4970==    by 0x5B8F63: PyObject_Malloc (in /usr/bin/python3.8)
==4970==    by 0x5CDC05: ??? (in /usr/bin/python3.8)
==4970==    by 0x5CEEEF: PyDict_SetItem (in /usr/bin/python3.8)
==4970==    by 0x5BFE1F: PyObject_SetAttr (in /usr/bin/python3.8)
==4970==    by 0x5C235C: ??? (in /usr/bin/python3.8)
==4970==    by 0x6A55B1: PyModule_AddFunctions (in /usr/bin/python3.8)
==4970==    by 0x6A5829: _PyModule_CreateInitialized (in /usr/bin/python3.8)
==4970==    by 0x5FE218: _PyBuiltin_Init (in /usr/bin/python3.8)
==4970==    by 0x67FE1D: Py_InitializeFromConfig (in /usr/bin/python3.8)
==4970==    by 0x6B63F5: ??? (in /usr/bin/python3.8)
==4970==    by 0x6B6450: ??? (in /usr/bin/python3.8)
==4970== 
==4970== 
==4970== 1 errors in context 21 of 34:
==4970== Invalid read of size 4
==4970==    at 0x5B8222: PyObject_Free (in /usr/bin/python3.8)
==4970==    by 0x5CDC77: ??? (in /usr/bin/python3.8)
==4970==    by 0x5CEEEF: PyDict_SetItem (in /usr/bin/python3.8)
==4970==    by 0x59F100: PyType_Ready (in /usr/bin/python3.8)
==4970==    by 0x6A4892: _PyTypes_Init (in /usr/bin/python3.8)
==4970==    by 0x67FD5B: Py_InitializeFromConfig (in /usr/bin/python3.8)
==4970==    by 0x6B63F5: ??? (in /usr/bin/python3.8)
==4970==    by 0x6B6450: ??? (in /usr/bin/python3.8)
==4970==    by 0x6B64BC: Py_BytesMain (in /usr/bin/python3.8)
==4970==    by 0x48910B2: (below main) (libc-start.c:308)
==4970==  Address 0x4c3a020 is 208 bytes inside a block of size 576 free'd
==4970==    at 0x483CA3F: free (in /usr/lib/x86_64-linux-gnu/valgrind/vgpreload_memcheck-amd64-linux.so)
==4970==    by 0x5CDC77: ??? (in /usr/bin/python3.8)
==4970==    by 0x5CEEEF: PyDict_SetItem (in /usr/bin/python3.8)
==4970==    by 0x59E747: PyType_Ready (in /usr/bin/python3.8)
==4970==    by 0x6A486E: _PyTypes_Init (in /usr/bin/python3.8)
==4970==    by 0x67FD5B: Py_InitializeFromConfig (in /usr/bin/python3.8)
==4970==    by 0x6B63F5: ??? (in /usr/bin/python3.8)
==4970==    by 0x6B6450: ??? (in /usr/bin/python3.8)
==4970==    by 0x6B64BC: Py_BytesMain (in /usr/bin/python3.8)
==4970==    by 0x48910B2: (below main) (libc-start.c:308)
==4970==  Block was alloc'd at
==4970==    at 0x483B7F3: malloc (in /usr/lib/x86_64-linux-gnu/valgrind/vgpreload_memcheck-amd64-linux.so)
==4970==    by 0x5B8F63: PyObject_Malloc (in /usr/bin/python3.8)
==4970==    by 0x5CDC05: ??? (in /usr/bin/python3.8)
==4970==    by 0x5CEEEF: PyDict_SetItem (in /usr/bin/python3.8)
==4970==    by 0x59E4CD: PyType_Ready (in /usr/bin/python3.8)
==4970==    by 0x6A486E: _PyTypes_Init (in /usr/bin/python3.8)
==4970==    by 0x67FD5B: Py_InitializeFromConfig (in /usr/bin/python3.8)
==4970==    by 0x6B63F5: ??? (in /usr/bin/python3.8)
==4970==    by 0x6B6450: ??? (in /usr/bin/python3.8)
==4970==    by 0x6B64BC: Py_BytesMain (in /usr/bin/python3.8)
==4970==    by 0x48910B2: (below main) (libc-start.c:308)
==4970== 
==4970== 
==4970== 1 errors in context 22 of 34:
==4970== Invalid read of size 4
==4970==    at 0x5B8222: PyObject_Free (in /usr/bin/python3.8)
==4970==    by 0x5CDC77: ??? (in /usr/bin/python3.8)
==4970==    by 0x5CEEEF: PyDict_SetItem (in /usr/bin/python3.8)
==4970==    by 0x5A04BE: PyType_Ready (in /usr/bin/python3.8)
==4970==    by 0x6A4772: _PyTypes_Init (in /usr/bin/python3.8)
==4970==    by 0x67FD5B: Py_InitializeFromConfig (in /usr/bin/python3.8)
==4970==    by 0x6B63F5: ??? (in /usr/bin/python3.8)
==4970==    by 0x6B6450: ??? (in /usr/bin/python3.8)
==4970==    by 0x6B64BC: Py_BytesMain (in /usr/bin/python3.8)
==4970==    by 0x48910B2: (below main) (libc-start.c:308)
==4970==  Address 0x4c2f020 is 624 bytes inside a block of size 2,208 free'd
==4970==    at 0x483CA3F: free (in /usr/lib/x86_64-linux-gnu/valgrind/vgpreload_memcheck-amd64-linux.so)
==4970==    by 0x5CDC77: ??? (in /usr/bin/python3.8)
==4970==    by 0x5CFD32: PyDict_SetDefault (in /usr/bin/python3.8)
==4970==    by 0x575811: PyUnicode_InternFromString (in /usr/bin/python3.8)
==4970==    by 0x5A0226: PyType_Ready (in /usr/bin/python3.8)
==4970==    by 0x6A4772: _PyTypes_Init (in /usr/bin/python3.8)
==4970==    by 0x67FD5B: Py_InitializeFromConfig (in /usr/bin/python3.8)
==4970==    by 0x6B63F5: ??? (in /usr/bin/python3.8)
==4970==    by 0x6B6450: ??? (in /usr/bin/python3.8)
==4970==    by 0x6B64BC: Py_BytesMain (in /usr/bin/python3.8)
==4970==    by 0x48910B2: (below main) (libc-start.c:308)
==4970==  Block was alloc'd at
==4970==    at 0x483B7F3: malloc (in /usr/lib/x86_64-linux-gnu/valgrind/vgpreload_memcheck-amd64-linux.so)
==4970==    by 0x5B8F63: PyObject_Malloc (in /usr/bin/python3.8)
==4970==    by 0x5CDC05: ??? (in /usr/bin/python3.8)
==4970==    by 0x5CFD32: PyDict_SetDefault (in /usr/bin/python3.8)
==4970==    by 0x575811: PyUnicode_InternFromString (in /usr/bin/python3.8)
==4970==    by 0x69D1C0: ??? (in /usr/bin/python3.8)
==4970==    by 0x5A1289: PyType_Ready (in /usr/bin/python3.8)
==4970==    by 0x6A4772: _PyTypes_Init (in /usr/bin/python3.8)
==4970==    by 0x67FD5B: Py_InitializeFromConfig (in /usr/bin/python3.8)
==4970==    by 0x6B63F5: ??? (in /usr/bin/python3.8)
==4970==    by 0x6B6450: ??? (in /usr/bin/python3.8)
==4970==    by 0x6B64BC: Py_BytesMain (in /usr/bin/python3.8)
==4970== 
==4970== 
==4970== 2 errors in context 23 of 34:
==4970== Invalid read of size 4
==4970==    at 0x5EB64C: ??? (in /usr/bin/python3.8)
==4970==    by 0x680907: PyMarshal_ReadObjectFromString (in /usr/bin/python3.8)
==4970==    by 0x5C3A3F: ??? (in /usr/bin/python3.8)
==4970==    by 0x5F257C: PyVectorcall_Call (in /usr/bin/python3.8)
==4970==    by 0x56FCB5: _PyEval_EvalFrameDefault (in /usr/bin/python3.8)
==4970==    by 0x568229: _PyEval_EvalCodeWithName (in /usr/bin/python3.8)
==4970==    by 0x5F6032: _PyFunction_Vectorcall (in /usr/bin/python3.8)
==4970==    by 0x569F5D: _PyEval_EvalFrameDefault (in /usr/bin/python3.8)
==4970==    by 0x5F5E55: _PyFunction_Vectorcall (in /usr/bin/python3.8)
==4970==    by 0x56EF96: _PyEval_EvalFrameDefault (in /usr/bin/python3.8)
==4970==    by 0x5F5E55: _PyFunction_Vectorcall (in /usr/bin/python3.8)
==4970==    by 0x569F5D: _PyEval_EvalFrameDefault (in /usr/bin/python3.8)
==4970==  Address 0x4c6a020 is 1,744 bytes inside a block of size 2,152 free'd
==4970==    at 0x483DFAF: realloc (in /usr/lib/x86_64-linux-gnu/valgrind/vgpreload_memcheck-amd64-linux.so)
==4970==    by 0x5EA784: PyList_Append (in /usr/bin/python3.8)
==4970==    by 0x54DC88: ??? (in /usr/bin/python3.8)
==4970==    by 0x54DD0E: ??? (in /usr/bin/python3.8)
==4970==    by 0x54DD35: ??? (in /usr/bin/python3.8)
==4970==    by 0x54E312: ??? (in /usr/bin/python3.8)
==4970==    by 0x54DDAA: ??? (in /usr/bin/python3.8)
==4970==    by 0x54E312: ??? (in /usr/bin/python3.8)
==4970==    by 0x54DE61: ??? (in /usr/bin/python3.8)
==4970==    by 0x54E312: ??? (in /usr/bin/python3.8)
==4970==    by 0x6808F4: PyMarshal_ReadObjectFromString (in /usr/bin/python3.8)
==4970==    by 0x5C3A3F: ??? (in /usr/bin/python3.8)
==4970==  Block was alloc'd at
==4970==    at 0x483DFAF: realloc (in /usr/lib/x86_64-linux-gnu/valgrind/vgpreload_memcheck-amd64-linux.so)
==4970==    by 0x5EA784: PyList_Append (in /usr/bin/python3.8)
==4970==    by 0x54DC88: ??? (in /usr/bin/python3.8)
==4970==    by 0x54DD5C: ??? (in /usr/bin/python3.8)
==4970==    by 0x54E328: ??? (in /usr/bin/python3.8)
==4970==    by 0x54DE61: ??? (in /usr/bin/python3.8)
==4970==    by 0x54E312: ??? (in /usr/bin/python3.8)
==4970==    by 0x54DE61: ??? (in /usr/bin/python3.8)
==4970==    by 0x54E312: ??? (in /usr/bin/python3.8)
==4970==    by 0x6808F4: PyMarshal_ReadObjectFromString (in /usr/bin/python3.8)
==4970==    by 0x5C3A3F: ??? (in /usr/bin/python3.8)
==4970==    by 0x5F257C: PyVectorcall_Call (in /usr/bin/python3.8)
==4970== 
==4970== 
==4970== 2 errors in context 24 of 34:
==4970== Invalid read of size 4
==4970==    at 0x5B9C3A: PyMem_Realloc (in /usr/bin/python3.8)
==4970==    by 0x5EA784: PyList_Append (in /usr/bin/python3.8)
==4970==    by 0x54DC88: ??? (in /usr/bin/python3.8)
==4970==    by 0x54E394: ??? (in /usr/bin/python3.8)
==4970==    by 0x54DE61: ??? (in /usr/bin/python3.8)
==4970==    by 0x54E312: ??? (in /usr/bin/python3.8)
==4970==    by 0x6808F4: PyMarshal_ReadObjectFromString (in /usr/bin/python3.8)
==4970==    by 0x68310F: PyImport_ImportFrozenModuleObject (in /usr/bin/python3.8)
==4970==    by 0x6831B1: PyImport_ImportFrozenModule (in /usr/bin/python3.8)
==4970==    by 0x67EDC0: ??? (in /usr/bin/python3.8)
==4970==    by 0x67FF0B: Py_InitializeFromConfig (in /usr/bin/python3.8)
==4970==    by 0x6B63F5: ??? (in /usr/bin/python3.8)
==4970==  Address 0x4c53020 is 416 bytes inside a block of size 1,008 free'd
==4970==    at 0x483DFAF: realloc (in /usr/lib/x86_64-linux-gnu/valgrind/vgpreload_memcheck-amd64-linux.so)
==4970==    by 0x5EA784: PyList_Append (in /usr/bin/python3.8)
==4970==    by 0x54DC88: ??? (in /usr/bin/python3.8)
==4970==    by 0x54DD83: ??? (in /usr/bin/python3.8)
==4970==    by 0x54E328: ??? (in /usr/bin/python3.8)
==4970==    by 0x54DE61: ??? (in /usr/bin/python3.8)
==4970==    by 0x54E312: ??? (in /usr/bin/python3.8)
==4970==    by 0x54DE61: ??? (in /usr/bin/python3.8)
==4970==    by 0x54E312: ??? (in /usr/bin/python3.8)
==4970==    by 0x6808F4: PyMarshal_ReadObjectFromString (in /usr/bin/python3.8)
==4970==    by 0x68310F: PyImport_ImportFrozenModuleObject (in /usr/bin/python3.8)
==4970==    by 0x6831B1: PyImport_ImportFrozenModule (in /usr/bin/python3.8)
==4970==  Block was alloc'd at
==4970==    at 0x483DFAF: realloc (in /usr/lib/x86_64-linux-gnu/valgrind/vgpreload_memcheck-amd64-linux.so)
==4970==    by 0x5EA784: PyList_Append (in /usr/bin/python3.8)
==4970==    by 0x54DC88: ??? (in /usr/bin/python3.8)
==4970==    by 0x54DDD1: ??? (in /usr/bin/python3.8)
==4970==    by 0x54E328: ??? (in /usr/bin/python3.8)
==4970==    by 0x54DE61: ??? (in /usr/bin/python3.8)
==4970==    by 0x54E312: ??? (in /usr/bin/python3.8)
==4970==    by 0x6808F4: PyMarshal_ReadObjectFromString (in /usr/bin/python3.8)
==4970==    by 0x68310F: PyImport_ImportFrozenModuleObject (in /usr/bin/python3.8)
==4970==    by 0x6831B1: PyImport_ImportFrozenModule (in /usr/bin/python3.8)
==4970==    by 0x67EDC0: ??? (in /usr/bin/python3.8)
==4970==    by 0x67FF0B: Py_InitializeFromConfig (in /usr/bin/python3.8)
==4970== 
==4970== 
==4970== 2 errors in context 25 of 34:
==4970== Invalid read of size 4
==4970==    at 0x5B9C3A: PyMem_Realloc (in /usr/bin/python3.8)
==4970==    by 0x5EA784: PyList_Append (in /usr/bin/python3.8)
==4970==    by 0x54DC88: ??? (in /usr/bin/python3.8)
==4970==    by 0x54DD5C: ??? (in /usr/bin/python3.8)
==4970==    by 0x54E328: ??? (in /usr/bin/python3.8)
==4970==    by 0x54DE61: ??? (in /usr/bin/python3.8)
==4970==    by 0x54E312: ??? (in /usr/bin/python3.8)
==4970==    by 0x6808F4: PyMarshal_ReadObjectFromString (in /usr/bin/python3.8)
==4970==    by 0x5C3A3F: ??? (in /usr/bin/python3.8)
==4970==    by 0x5F257C: PyVectorcall_Call (in /usr/bin/python3.8)
==4970==    by 0x56FCB5: _PyEval_EvalFrameDefault (in /usr/bin/python3.8)
==4970==    by 0x568229: _PyEval_EvalCodeWithName (in /usr/bin/python3.8)
==4970==  Address 0x4c67020 is 512 bytes inside a block of size 704 free'd
==4970==    at 0x483DFAF: realloc (in /usr/lib/x86_64-linux-gnu/valgrind/vgpreload_memcheck-amd64-linux.so)
==4970==    by 0x5EA784: PyList_Append (in /usr/bin/python3.8)
==4970==    by 0x54DC88: ??? (in /usr/bin/python3.8)
==4970==    by 0x54DE61: ??? (in /usr/bin/python3.8)
==4970==    by 0x54E328: ??? (in /usr/bin/python3.8)
==4970==    by 0x54DE61: ??? (in /usr/bin/python3.8)
==4970==    by 0x54E312: ??? (in /usr/bin/python3.8)
==4970==    by 0x6808F4: PyMarshal_ReadObjectFromString (in /usr/bin/python3.8)
==4970==    by 0x5C3A3F: ??? (in /usr/bin/python3.8)
==4970==    by 0x5F257C: PyVectorcall_Call (in /usr/bin/python3.8)
==4970==    by 0x56FCB5: _PyEval_EvalFrameDefault (in /usr/bin/python3.8)
==4970==    by 0x568229: _PyEval_EvalCodeWithName (in /usr/bin/python3.8)
==4970==  Block was alloc'd at
==4970==    at 0x483DFAF: realloc (in /usr/lib/x86_64-linux-gnu/valgrind/vgpreload_memcheck-amd64-linux.so)
==4970==    by 0x5EA784: PyList_Append (in /usr/bin/python3.8)
==4970==    by 0x54DFB2: ??? (in /usr/bin/python3.8)
==4970==    by 0x54DE1B: ??? (in /usr/bin/python3.8)
==4970==    by 0x54E312: ??? (in /usr/bin/python3.8)
==4970==    by 0x54DE61: ??? (in /usr/bin/python3.8)
==4970==    by 0x54E312: ??? (in /usr/bin/python3.8)
==4970==    by 0x6808F4: PyMarshal_ReadObjectFromString (in /usr/bin/python3.8)
==4970==    by 0x5C3A3F: ??? (in /usr/bin/python3.8)
==4970==    by 0x5F257C: PyVectorcall_Call (in /usr/bin/python3.8)
==4970==    by 0x56FCB5: _PyEval_EvalFrameDefault (in /usr/bin/python3.8)
==4970==    by 0x568229: _PyEval_EvalCodeWithName (in /usr/bin/python3.8)
==4970== 
==4970== 
==4970== 2 errors in context 26 of 34:
==4970== Invalid read of size 4
==4970==    at 0x5B9C3A: PyMem_Realloc (in /usr/bin/python3.8)
==4970==    by 0x5EA784: PyList_Append (in /usr/bin/python3.8)
==4970==    by 0x54DC88: ??? (in /usr/bin/python3.8)
==4970==    by 0x54DD35: ??? (in /usr/bin/python3.8)
==4970==    by 0x54E328: ??? (in /usr/bin/python3.8)
==4970==    by 0x54DD35: ??? (in /usr/bin/python3.8)
==4970==    by 0x54E312: ??? (in /usr/bin/python3.8)
==4970==    by 0x54DE61: ??? (in /usr/bin/python3.8)
==4970==    by 0x54E312: ??? (in /usr/bin/python3.8)
==4970==    by 0x6808F4: PyMarshal_ReadObjectFromString (in /usr/bin/python3.8)
==4970==    by 0x68310F: PyImport_ImportFrozenModuleObject (in /usr/bin/python3.8)
==4970==    by 0x6831B1: PyImport_ImportFrozenModule (in /usr/bin/python3.8)
==4970==  Address 0x4c52020 is 16 bytes before a block of size 76 alloc'd
==4970==    at 0x483B7F3: malloc (in /usr/lib/x86_64-linux-gnu/valgrind/vgpreload_memcheck-amd64-linux.so)
==4970==    by 0x6A39EA: _PyMem_RawWcsdup (in /usr/bin/python3.8)
==4970==    by 0x67F9F1: ??? (in /usr/bin/python3.8)
==4970==    by 0x67FBA5: _PyConfig_WritePathConfig (in /usr/bin/python3.8)
==4970==    by 0x67FEDF: Py_InitializeFromConfig (in /usr/bin/python3.8)
==4970==    by 0x6B63F5: ??? (in /usr/bin/python3.8)
==4970==    by 0x6B6450: ??? (in /usr/bin/python3.8)
==4970==    by 0x6B64BC: Py_BytesMain (in /usr/bin/python3.8)
==4970==    by 0x48910B2: (below main) (libc-start.c:308)
==4970== 
==4970== 
==4970== 2 errors in context 27 of 34:
==4970== Invalid read of size 4
==4970==    at 0x5B9C3A: PyMem_Realloc (in /usr/bin/python3.8)
==4970==    by 0x5EA784: PyList_Append (in /usr/bin/python3.8)
==4970==    by 0x54DC88: ??? (in /usr/bin/python3.8)
==4970==    by 0x54DD83: ??? (in /usr/bin/python3.8)
==4970==    by 0x54E328: ??? (in /usr/bin/python3.8)
==4970==    by 0x54DE61: ??? (in /usr/bin/python3.8)
==4970==    by 0x54E312: ??? (in /usr/bin/python3.8)
==4970==    by 0x6808F4: PyMarshal_ReadObjectFromString (in /usr/bin/python3.8)
==4970==    by 0x68310F: PyImport_ImportFrozenModuleObject (in /usr/bin/python3.8)
==4970==    by 0x6831B1: PyImport_ImportFrozenModule (in /usr/bin/python3.8)
==4970==    by 0x67EDC0: ??? (in /usr/bin/python3.8)
==4970==    by 0x67FF0B: Py_InitializeFromConfig (in /usr/bin/python3.8)
==4970==  Address 0x4c52020 is 16 bytes before a block of size 76 alloc'd
==4970==    at 0x483B7F3: malloc (in /usr/lib/x86_64-linux-gnu/valgrind/vgpreload_memcheck-amd64-linux.so)
==4970==    by 0x6A39EA: _PyMem_RawWcsdup (in /usr/bin/python3.8)
==4970==    by 0x67F9F1: ??? (in /usr/bin/python3.8)
==4970==    by 0x67FBA5: _PyConfig_WritePathConfig (in /usr/bin/python3.8)
==4970==    by 0x67FEDF: Py_InitializeFromConfig (in /usr/bin/python3.8)
==4970==    by 0x6B63F5: ??? (in /usr/bin/python3.8)
==4970==    by 0x6B6450: ??? (in /usr/bin/python3.8)
==4970==    by 0x6B64BC: Py_BytesMain (in /usr/bin/python3.8)
==4970==    by 0x48910B2: (below main) (libc-start.c:308)
==4970== 
==4970== 
==4970== 2 errors in context 28 of 34:
==4970== Invalid read of size 4
==4970==    at 0x5B8222: PyObject_Free (in /usr/bin/python3.8)
==4970==    by 0x5CDC77: ??? (in /usr/bin/python3.8)
==4970==    by 0x5CEEEF: PyDict_SetItem (in /usr/bin/python3.8)
==4970==    by 0x5A02FE: PyType_Ready (in /usr/bin/python3.8)
==4970==    by 0x6A47F0: _PyTypes_Init (in /usr/bin/python3.8)
==4970==    by 0x67FD5B: Py_InitializeFromConfig (in /usr/bin/python3.8)
==4970==    by 0x6B63F5: ??? (in /usr/bin/python3.8)
==4970==    by 0x6B6450: ??? (in /usr/bin/python3.8)
==4970==    by 0x6B64BC: Py_BytesMain (in /usr/bin/python3.8)
==4970==    by 0x48910B2: (below main) (libc-start.c:308)
==4970==  Address 0x4c34020 is 1,008 bytes inside a block of size 1,112 free'd
==4970==    at 0x483CA3F: free (in /usr/lib/x86_64-linux-gnu/valgrind/vgpreload_memcheck-amd64-linux.so)
==4970==    by 0x5CDC77: ??? (in /usr/bin/python3.8)
==4970==    by 0x5CEEEF: PyDict_SetItem (in /usr/bin/python3.8)
==4970==    by 0x59E4CD: PyType_Ready (in /usr/bin/python3.8)
==4970==    by 0x6A47CC: _PyTypes_Init (in /usr/bin/python3.8)
==4970==    by 0x67FD5B: Py_InitializeFromConfig (in /usr/bin/python3.8)
==4970==    by 0x6B63F5: ??? (in /usr/bin/python3.8)
==4970==    by 0x6B6450: ??? (in /usr/bin/python3.8)
==4970==    by 0x6B64BC: Py_BytesMain (in /usr/bin/python3.8)
==4970==    by 0x48910B2: (below main) (libc-start.c:308)
==4970==  Block was alloc'd at
==4970==    at 0x483B7F3: malloc (in /usr/lib/x86_64-linux-gnu/valgrind/vgpreload_memcheck-amd64-linux.so)
==4970==    by 0x5B8F63: PyObject_Malloc (in /usr/bin/python3.8)
==4970==    by 0x5CDC05: ??? (in /usr/bin/python3.8)
==4970==    by 0x5CEEEF: PyDict_SetItem (in /usr/bin/python3.8)
==4970==    by 0x59E4CD: PyType_Ready (in /usr/bin/python3.8)
==4970==    by 0x6A47CC: _PyTypes_Init (in /usr/bin/python3.8)
==4970==    by 0x67FD5B: Py_InitializeFromConfig (in /usr/bin/python3.8)
==4970==    by 0x6B63F5: ??? (in /usr/bin/python3.8)
==4970==    by 0x6B6450: ??? (in /usr/bin/python3.8)
==4970==    by 0x6B64BC: Py_BytesMain (in /usr/bin/python3.8)
==4970==    by 0x48910B2: (below main) (libc-start.c:308)
==4970== 
==4970== 
==4970== 3 errors in context 29 of 34:
==4970== Invalid read of size 4
==4970==    at 0x5B8222: PyObject_Free (in /usr/bin/python3.8)
==4970==    by 0x5D1AEB: ??? (in /usr/bin/python3.8)
==4970==    by 0x4F6871: ??? (in /usr/bin/python3.8)
==4970==    by 0x5C3B96: ??? (in /usr/bin/python3.8)
==4970==    by 0x569F5D: _PyEval_EvalFrameDefault (in /usr/bin/python3.8)
==4970==    by 0x568229: _PyEval_EvalCodeWithName (in /usr/bin/python3.8)
==4970==    by 0x68C1E6: PyEval_EvalCode (in /usr/bin/python3.8)
==4970==    by 0x5FF1F3: ??? (in /usr/bin/python3.8)
==4970==    by 0x5C3CAF: ??? (in /usr/bin/python3.8)
==4970==    by 0x569F5D: _PyEval_EvalFrameDefault (in /usr/bin/python3.8)
==4970==    by 0x5F5E55: _PyFunction_Vectorcall (in /usr/bin/python3.8)
==4970==    by 0x56EF96: _PyEval_EvalFrameDefault (in /usr/bin/python3.8)
==4970==  Address 0x4c6f020 is 16 bytes after a block of size 944 in arena "client"
==4970== 
==4970== 
==4970== 3 errors in context 30 of 34:
==4970== Invalid read of size 4
==4970==    at 0x5B8222: PyObject_Free (in /usr/bin/python3.8)
==4970==    by 0x5CDC77: ??? (in /usr/bin/python3.8)
==4970==    by 0x5CEEEF: PyDict_SetItem (in /usr/bin/python3.8)
==4970==    by 0x56ADFF: _PyEval_EvalFrameDefault (in /usr/bin/python3.8)
==4970==    by 0x568229: _PyEval_EvalCodeWithName (in /usr/bin/python3.8)
==4970==    by 0x68C1E6: PyEval_EvalCode (in /usr/bin/python3.8)
==4970==    by 0x683D86: ??? (in /usr/bin/python3.8)
==4970==    by 0x68314C: PyImport_ImportFrozenModuleObject (in /usr/bin/python3.8)
==4970==    by 0x6831B1: PyImport_ImportFrozenModule (in /usr/bin/python3.8)
==4970==    by 0x67EDC0: ??? (in /usr/bin/python3.8)
==4970==    by 0x67FF0B: Py_InitializeFromConfig (in /usr/bin/python3.8)
==4970==    by 0x6B63F5: ??? (in /usr/bin/python3.8)
==4970==  Address 0x4c5e020 is 848 bytes inside a block of size 1,864 free'd
==4970==    at 0x483CA3F: free (in /usr/lib/x86_64-linux-gnu/valgrind/vgpreload_memcheck-amd64-linux.so)
==4970==    by 0x5EB98C: ??? (in /usr/bin/python3.8)
==4970==    by 0x680907: PyMarshal_ReadObjectFromString (in /usr/bin/python3.8)
==4970==    by 0x68310F: PyImport_ImportFrozenModuleObject (in /usr/bin/python3.8)
==4970==    by 0x6831B1: PyImport_ImportFrozenModule (in /usr/bin/python3.8)
==4970==    by 0x67EDC0: ??? (in /usr/bin/python3.8)
==4970==    by 0x67FF0B: Py_InitializeFromConfig (in /usr/bin/python3.8)
==4970==    by 0x6B63F5: ??? (in /usr/bin/python3.8)
==4970==    by 0x6B6450: ??? (in /usr/bin/python3.8)
==4970==    by 0x6B64BC: Py_BytesMain (in /usr/bin/python3.8)
==4970==    by 0x48910B2: (below main) (libc-start.c:308)
==4970==  Block was alloc'd at
==4970==    at 0x483DFAF: realloc (in /usr/lib/x86_64-linux-gnu/valgrind/vgpreload_memcheck-amd64-linux.so)
==4970==    by 0x5EA784: PyList_Append (in /usr/bin/python3.8)
==4970==    by 0x54DFB2: ??? (in /usr/bin/python3.8)
==4970==    by 0x54DDD1: ??? (in /usr/bin/python3.8)
==4970==    by 0x54E312: ??? (in /usr/bin/python3.8)
==4970==    by 0x54DE61: ??? (in /usr/bin/python3.8)
==4970==    by 0x54E312: ??? (in /usr/bin/python3.8)
==4970==    by 0x6808F4: PyMarshal_ReadObjectFromString (in /usr/bin/python3.8)
==4970==    by 0x68310F: PyImport_ImportFrozenModuleObject (in /usr/bin/python3.8)
==4970==    by 0x6831B1: PyImport_ImportFrozenModule (in /usr/bin/python3.8)
==4970==    by 0x67EDC0: ??? (in /usr/bin/python3.8)
==4970==    by 0x67FF0B: Py_InitializeFromConfig (in /usr/bin/python3.8)
==4970== 
==4970== 
==4970== 5 errors in context 31 of 34:
==4970== Invalid read of size 4
==4970==    at 0x5B8222: PyObject_Free (in /usr/bin/python3.8)
==4970==    by 0x5CDC77: ??? (in /usr/bin/python3.8)
==4970==    by 0x5CFD32: PyDict_SetDefault (in /usr/bin/python3.8)
==4970==    by 0x575811: PyUnicode_InternFromString (in /usr/bin/python3.8)
==4970==    by 0x69D1C0: ??? (in /usr/bin/python3.8)
==4970==    by 0x5A1289: PyType_Ready (in /usr/bin/python3.8)
==4970==    by 0x6A4772: _PyTypes_Init (in /usr/bin/python3.8)
==4970==    by 0x67FD5B: Py_InitializeFromConfig (in /usr/bin/python3.8)
==4970==    by 0x6B63F5: ??? (in /usr/bin/python3.8)
==4970==    by 0x6B6450: ??? (in /usr/bin/python3.8)
==4970==    by 0x6B64BC: Py_BytesMain (in /usr/bin/python3.8)
==4970==    by 0x48910B2: (below main) (libc-start.c:308)
==4970==  Address 0x4c2e020 is 16 bytes before a block of size 28 alloc'd
==4970==    at 0x483B7F3: malloc (in /usr/lib/x86_64-linux-gnu/valgrind/vgpreload_memcheck-amd64-linux.so)
==4970==    by 0x6A39EA: _PyMem_RawWcsdup (in /usr/bin/python3.8)
==4970==    by 0x681588: PyConfig_SetString (in /usr/bin/python3.8)
==4970==    by 0x68190E: _PyConfig_Copy (in /usr/bin/python3.8)
==4970==    by 0x67FD04: Py_InitializeFromConfig (in /usr/bin/python3.8)
==4970==    by 0x6B63F5: ??? (in /usr/bin/python3.8)
==4970==    by 0x6B6450: ??? (in /usr/bin/python3.8)
==4970==    by 0x6B64BC: Py_BytesMain (in /usr/bin/python3.8)
==4970==    by 0x48910B2: (below main) (libc-start.c:308)
==4970== 
==4970== 
==4970== 7 errors in context 32 of 34:
==4970== Invalid read of size 4
==4970==    at 0x5B8222: PyObject_Free (in /usr/bin/python3.8)
==4970==    by 0x5CDC77: ??? (in /usr/bin/python3.8)
==4970==    by 0x5CEEEF: PyDict_SetItem (in /usr/bin/python3.8)
==4970==    by 0x59E4CD: PyType_Ready (in /usr/bin/python3.8)
==4970==    by 0x6A47A8: _PyTypes_Init (in /usr/bin/python3.8)
==4970==    by 0x67FD5B: Py_InitializeFromConfig (in /usr/bin/python3.8)
==4970==    by 0x6B63F5: ??? (in /usr/bin/python3.8)
==4970==    by 0x6B6450: ??? (in /usr/bin/python3.8)
==4970==    by 0x6B64BC: Py_BytesMain (in /usr/bin/python3.8)
==4970==    by 0x48910B2: (below main) (libc-start.c:308)
==4970==  Address 0x4c31020 is 16 bytes inside a block of size 576 free'd
==4970==    at 0x483CA3F: free (in /usr/lib/x86_64-linux-gnu/valgrind/vgpreload_memcheck-amd64-linux.so)
==4970==    by 0x5CDC77: ??? (in /usr/bin/python3.8)
==4970==    by 0x5CEEEF: PyDict_SetItem (in /usr/bin/python3.8)
==4970==    by 0x5A04BE: PyType_Ready (in /usr/bin/python3.8)
==4970==    by 0x6A4784: _PyTypes_Init (in /usr/bin/python3.8)
==4970==    by 0x67FD5B: Py_InitializeFromConfig (in /usr/bin/python3.8)
==4970==    by 0x6B63F5: ??? (in /usr/bin/python3.8)
==4970==    by 0x6B6450: ??? (in /usr/bin/python3.8)
==4970==    by 0x6B64BC: Py_BytesMain (in /usr/bin/python3.8)
==4970==    by 0x48910B2: (below main) (libc-start.c:308)
==4970==  Block was alloc'd at
==4970==    at 0x483B7F3: malloc (in /usr/lib/x86_64-linux-gnu/valgrind/vgpreload_memcheck-amd64-linux.so)
==4970==    by 0x5B8F63: PyObject_Malloc (in /usr/bin/python3.8)
==4970==    by 0x5CDC05: ??? (in /usr/bin/python3.8)
==4970==    by 0x5CEEEF: PyDict_SetItem (in /usr/bin/python3.8)
==4970==    by 0x5A02FE: PyType_Ready (in /usr/bin/python3.8)
==4970==    by 0x6A4784: _PyTypes_Init (in /usr/bin/python3.8)
==4970==    by 0x67FD5B: Py_InitializeFromConfig (in /usr/bin/python3.8)
==4970==    by 0x6B63F5: ??? (in /usr/bin/python3.8)
==4970==    by 0x6B6450: ??? (in /usr/bin/python3.8)
==4970==    by 0x6B64BC: Py_BytesMain (in /usr/bin/python3.8)
==4970==    by 0x48910B2: (below main) (libc-start.c:308)
==4970== 
==4970== ERROR SUMMARY: 54 errors from 34 contexts (suppressed: 0 from 0)
